Workbook
Name FIN_PROY: Calendario!$B$4
Name FERIADOS: Calendario!$F$8:$F$37
Name FECHA_ESTADO: Calendario!$B$5
Name FECHAS: Calendario!$A$8:$A$396
Name NLAB: Calendario!$D$8:$D$396

Sheet Predictivo
A1: CRONOGRAMA DETALLADO – DSC PUCP WORKSHOPS
A2: Developer Student Club PUCP · Gerente de Proyecto: Lucas Mattias Alvites Galarza · Elaborado por: Equipo 5 · Línea base v1.0 (alineada al Acta de Constitución y a la EDT validadas) · Calendario: lun–sáb sin feriados
A3: {="Fecha de estado (corte): "&TEXT(DAY(FECHA_ESTADO),"00")&"/"&TEXT(MONTH(FECHA_ESTADO),"00")&"/"&YEAR(FECHA_ESTADO)&" · Inicio: "&TEXT(DAY(Calendario!$B$3),"00")&"/"&TEXT(MONTH(Calendario!$B$3),"00")&"/"&YEAR(Calendario!$B$3)&" · Fin: "&TEXT(DAY(FIN_PROY),"00")&"/"&TEXT(MONTH(FIN_PROY),"00")&"/"&YEAR(FIN_PROY)&" · Duración: "&(INDEX(NLAB,MATCH(FIN_PROY,FECHAS,0))-INDEX(NLAB,MATCH(Calendario!$B$3,FECHAS,0))+1)&" días laborables"} -> Fecha de estado (corte): 26/09/2026 · Inicio: 14/09/2026 · Fin: 20/08/2027 · Duración: 279 días laborables | P3: SET 2026 | S3: OCT 2026 | W3: NOV 2026 | AB3: DIC 2026 | AF3: ENE 2027 | AJ3: FEB 2027 | AN3: MAR 2027 | AS3: ABR 2027 | AW3: MAY 2027 | BB3: JUN 2027 | BF3: JUL 2027 | BJ3: AGO 2027
C4: Leyenda del Gantt: | D4: Actividad de la ruta crítica | E4: Actividad | H4: Esfuerzo continuo | I4: Hito del Acta (Barras oscuras = resumen) | J4: Dato editable | P4: S1 | Q4: S2 | R4: S3 | S4: S4 | T4: S5 | U4: S6 | V4: S7 | W4: S8 | X4: S9 | Y4: S10 | Z4: S11 | AA4: S12 | AB4: S13 | AC4: S14 | AD4: S15 | AE4: S16 | AF4: S17 | AG4: S18 | AH4: S19 | AI4: S20 | AJ4: S21 | AK4: S22 | AL4: S23 | AM4: S24 | AN4: S25 | AO4: S26 | AP4: S27 | AQ4: S28 | AR4: S29 | AS4: S30 | AT4: S31 | AU4: S32 | AV4: S33 | AW4: S34 | AX4: S35 | AY4: S36 | AZ4: S37 | BA4: S38 | BB4: S39 | BC4: S40 | BD4: S41 | BE4: S42 | BF4: S43 | BG4: S44 | BH4: S45 | BI4: S46 | BJ4: S47 | BK4: S48 | BL4: S49 | BM4: S50
N5: Semana (lunes) → | P5: =Calendario!$B$3-WEEKDAY(Calendario!$B$3,3) -> 46279 | Q5: =P5+7 -> 46286 | R5: =Q5+7 -> 46293 | S5: =R5+7 -> 46300 | T5: =S5+7 -> 46307 | U5: =T5+7 -> 46314 | V5: =U5+7 -> 46321 | W5: =V5+7 -> 46328 | X5: =W5+7 -> 46335 | ... BM5: =BL5+7 -> 46622
A6: FASE | B6: ID | C6: ENTREGABLE | D6: NOMBRE DE LA TAREA | E6: DURACIÓN (DÍAS) | F6: FECHA DE INICIO | G6: FECHA DE FIN | H6: PREDECESORAS | I6: RECURSOS ASIGNADOS | J6: ESTADO | K6: % DE AVANCE | L6: HOLGURA LIBRE (días) | M6: HOLGURA TOTAL (días) | N6: RUTA CRÍTICA
A7: Hitos | B7: 0 | C7: HITOS DEL PROYECTO (ACTA DE CONSTITUCIÓN) | E7: {=INDEX(NLAB,MATCH(G7,FECHAS,0))-INDEX(NLAB,MATCH(F7,FECHAS,0))+1} -> 279 | F7: =MIN(F8:F29) -> 46279 | G7: =MAX(G8:G29) -> 46619 | J7: =IF(K7>=1,"Completado",IF(AND(G7<FECHA_ESTADO,K7<1),"Atrasado",IF(K7>0,"En progreso","No iniciado"))) -> En progreso | K7: =IFERROR(AVERAGE(K8:K29),0) -> 0.090909091
A8: Inicio | B8: H01 | C8: Acta · fecha tope Acta: 14/09/2026 | D8: Acta de Constitución aprobada y Gerente de Proyecto designado | E8: 0 | F8: =MAX($G$32) -> 46279 | G8: =F8 -> 46279 | H8: 1.1.1 | I8: Hito de control (duración 0) | J8: {=IF(K8>=1,"Cumplido",IF(FECHA_ESTADO>DATE(2026,9,14),"Atrasado",IF(INDEX(NLAB,MATCH(DATE(2026,9,14),FECHAS,0))-INDEX(NLAB,MATCH(F8,FECHAS,0))<0,"En riesgo","Pendiente")))} -> Cumplido | K8: =IF(MIN($K$32)>=1,1,0) -> 1 | L8: {=INDEX(NLAB,MATCH(DATE(2026,9,14),FECHAS,0))-INDEX(NLAB,MATCH(F8,FECHAS,0))} -> 0 | M8: - | N8: Hito | P8: =IF(AND($F8>=P$5,$F8<=P$5+6),"*","") -> * | Q8: =IF(AND($F8>=Q$5,$F8<=Q$5+6),"*","") | R8: =IF(AND($F8>=R$5,$F8<=R$5+6),"*","") | S8: =IF(AND($F8>=S$5,$F8<=S$5+6),"*","") | T8: =IF(AND($F8>=T$5,$F8<=T$5+6),"*","") | U8: =IF(AND($F8>=U$5,$F8<=U$5+6),"*","") | V8: =IF(AND($F8>=V$5,$F8<=V$5+6),"*","") | W8: =IF(AND($F8>=W$5,$F8<=W$5+6),"*","") | ... BL8: =IF(AND($F8>=BL$5,$F8<=BL$5+6),"*","") | BM8: =IF(AND($F8>=BM$5,$F8<=BM$5+6),"◆","")
A9: Inicio | B9: H02 | C9: Insumo E1 · fecha tope Acta: 21/09/2026 | D9: Reunión de lanzamiento (kick-off) y responsables por área asignados | E9: 0 | F9: =MAX($G$42) -> 46286 | G9: =F9 -> 46286 | H9: 1.4.2 | I9: Hito de control (duración 0) | J9: {=IF(K9>=1,"Cumplido",IF(FECHA_ESTADO>DATE(2026,9,21),"Atrasado",IF(INDEX(NLAB,MATCH(DATE(2026,9,21),FECHAS,0))-INDEX(NLAB,MATCH(F9,FECHAS,0))<0,"En riesgo","Pendiente")))} -> Cumplido | K9: =IF(MIN($K$42)>=1,1,0) -> 1 | L9: {=INDEX(NLAB,MATCH(DATE(2026,9,21),FECHAS,0))-INDEX(NLAB,MATCH(F9,FECHAS,0))} -> 0 | M9: - | N9: Hito | P9: =IF(AND($F9>=P$5,$F9<=P$5+6),"◆","") | Q9: =IF(AND($F9>=Q$5,$F9<=Q$5+6),"*","") -> * | R9: =IF(AND($F9>=R$5,$F9<=R$5+6),"◆","") | S9: =IF(AND($F9>=S$5,$F9<=S$5+6),"◆","") | T9: =IF(AND($F9>=T$5,$F9<=T$5+6),"◆","") | U9: =IF(AND($F9>=U$5,$F9<=U$5+6),"◆","") | V9: =IF(AND($F9>=V$5,$F9<=V$5+6),"◆","") | W9: =IF(AND($F9>=W$5,$F9<=W$5+6),"◆","") | X9: =IF(AND($F9>=X$5,$F9<=X$5+6),"◆","") | Y9: =IF(AND($F9>=Y$5,$F9<=Y$5+6),"◆","") | ... BM9: =IF(AND($F9>=BM$5,$F9<=BM$5+6),"◆","")
A10: Planificación | B10: H03 | C10: E1 · fecha tope Acta: 30/10/2026 | D10: Plan para la Dirección del Proyecto aprobado | E10: 0 | F10: =MAX($G$47) -> 46325 | G10: =F10 -> 46325 | H10: 2.1.3 | I10: Hito de control (duración 0) | J10: {=IF(K10>=1,"Cumplido",IF(FECHA_ESTADO>DATE(2026,10,30),"Atrasado",IF(INDEX(NLAB,MATCH(DATE(2026,10,30),FECHAS,0))-INDEX(NLAB,MATCH(F10,FECHAS,0))<0,"En riesgo","Pendiente")))} -> Pendiente | K10: =IF(MIN($K$47)>=1,1,0) -> 0 | L10: {=INDEX(NLAB,MATCH(DATE(2026,10,30),FECHAS,0))-INDEX(NLAB,MATCH(F10,FECHAS,0))} -> 0 | M10: - | N10: Hito | P10: =IF(AND($F10>=P$5,$F10<=P$5+6),"◆","") | Q10: =IF(AND($F10>=Q$5,$F10<=Q$5+6),"◆","") | R10: =IF(AND($F10>=R$5,$F10<=R$5+6),"◆","") | S10: =IF(AND($F10>=S$5,$F10<=S$5+6),"◆","") | T10: =IF(AND($F10>=T$5,$F10<=T$5+6),"◆","") | U10: =IF(AND($F10>=U$5,$F10<=U$5+6),"◆","") | V10: =IF(AND($F10>=V$5,$F10<=V$5+6),"*","") -> * | W10: =IF(AND($F10>=W$5,$F10<=W$5+6),"◆","") | X10: =IF(AND($F10>=X$5,$F10<=X$5+6),"◆","") | Y10: =IF(AND($F10>=Y$5,$F10<=Y$5+6),"◆","") | Z10: =IF(AND($F10>=Z$5,$F10<=Z$5+6),"◆","") | AA10: =IF(AND($F10>=AA$5,$F10<=AA$5+6),"◆","") | AB10: =IF(AND($F10>=AB$5,$F10<=AB$5+6),"◆","") | AC10: =IF(AND($F10>=AC$5,$F10<=AC$5+6),"◆","") | AD10: =IF(AND($F10>=AD$5,$F10<=AD$5+6),"◆","") | ... BM10: =IF(AND($F10>=BM$5,$F10<=BM$5+6),"◆","")
A11: Planificación | B11: H04 | C11: E3 · fecha tope Acta: 06/11/2026 | D11: Inicio formal de la gestión de auspicios (brochure enviado) | E11: 0 | F11: =MAX($G$77) -> 46332 | G11: =F11 -> 46332 | H11: 3.1.1.2 | I11: Hito de control (duración 0) | J11: {=IF(K11>=1,"Cumplido",IF(FECHA_ESTADO>DATE(2026,11,6),"Atrasado",IF(INDEX(NLAB,MATCH(DATE(2026,11,6),FECHAS,0))-INDEX(NLAB,MATCH(F11,FECHAS,0))<0,"En riesgo","Pendiente")))} -> Pendiente | K11: =IF(MIN($K$77)>=1,1,0) -> 0 | L11: {=INDEX(NLAB,MATCH(DATE(2026,11,6),FECHAS,0))-INDEX(NLAB,MATCH(F11,FECHAS,0))} -> 0 | M11: - | N11: Hito | P11: =IF(AND($F11>=P$5,$F11<=P$5+6),"◆","") | Q11: =IF(AND($F11>=Q$5,$F11<=Q$5+6),"◆","") | R11: =IF(AND($F11>=R$5,$F11<=R$5+6),"◆","") | S11: =IF(AND($F11>=S$5,$F11<=S$5+6),"◆","") | T11: =IF(AND($F11>=T$5,$F11<=T$5+6),"◆","") | U11: =IF(AND($F11>=U$5,$F11<=U$5+6),"◆","") | V11: =IF(AND($F11>=V$5,$F11<=V$5+6),"◆","") | W11: =IF(AND($F11>=W$5,$F11<=W$5+6),"*","") -> * | X11: =IF(AND($F11>=X$5,$F11<=X$5+6),"◆","") | Y11: =IF(AND($F11>=Y$5,$F11<=Y$5+6),"◆","") | Z11: =IF(AND($F11>=Z$5,$F11<=Z$5+6),"◆","") | AA11: =IF(AND($F11>=AA$5,$F11<=AA$5+6),"◆","") | AB11: =IF(AND($F11>=AB$5,$F11<=AB$5+6),"◆","") | AC11: =IF(AND($F11>=AC$5,$F11<=AC$5+6),"◆","") | AD11: =IF(AND($F11>=AD$5,$F11<=AD$5+6),"◆","") | AE11: =IF(AND($F11>=AE$5,$F11<=AE$5+6),"◆","") | ... BM11: =IF(AND($F11>=BM$5,$F11<=BM$5+6),"◆","")
A12: Planificación | B12: H05 | C12: E2 · fecha tope Acta: 15/01/2027 | D12: Espacios y permisos confirmados (sede alternativa por evento) | E12: 0 | F12: =MAX($G$113,$G$143,$G$173,$G$204,$G$231,$G$259,$G$287,$G$288) -> 46402 | G12: =F12 -> 46402 | H12: 3.3.2.1, 3.4.2.1, 3.5.2.1, 3.6.2.1, 3.7.2.1, 3.8.2.1, 3.9.2.1, 3.9.2.2 | I12: Hito de control (duración 0) | J12: {=IF(K12>=1,"Cumplido",IF(FECHA_ESTADO>DATE(2027,1,15),"Atrasado",IF(INDEX(NLAB,MATCH(DATE(2027,1,15),FECHAS,0))-INDEX(NLAB,MATCH(F12,FECHAS,0))<0,"En riesgo","Pendiente")))} -> Pendiente | K12: =IF(MIN($K$113,$K$143,$K$173,$K$204,$K$231,$K$259,$K$287,$K$288)>=1,1,0) -> 0 | L12: {=INDEX(NLAB,MATCH(DATE(2027,1,15),FECHAS,0))-INDEX(NLAB,MATCH(F12,FECHAS,0))} -> 0 | M12: - | N12: Hito | P12: =IF(AND($F12>=P$5,$F12<=P$5+6),"◆","") | Q12: =IF(AND($F12>=Q$5,$F12<=Q$5+6),"◆","") | R12: =IF(AND($F12>=R$5,$F12<=R$5+6),"◆","") | S12: =IF(AND($F12>=S$5,$F12<=S$5+6),"◆","") | T12: =IF(AND($F12>=T$5,$F12<=T$5+6),"◆","") | U12: =IF(AND($F12>=U$5,$F12<=U$5+6),"◆","") | V12: =IF(AND($F12>=V$5,$F12<=V$5+6),"◆","") | W12: =IF(AND($F12>=W$5,$F12<=W$5+6),"◆","") | ... AF12: =IF(AND($F12>=AF$5,$F12<=AF$5+6),"◆","") | AG12: =IF(AND($F12>=AG$5,$F12<=AG$5+6),"*","") -> * | AH12: =IF(AND($F12>=AH$5,$F12<=AH$5+6),"◆","") | AI12: =IF(AND($F12>=AI$5,$F12<=AI$5+6),"◆","") | AJ12: =IF(AND($F12>=AJ$5,$F12<=AJ$5+6),"◆","") | AK12: =IF(AND($F12>=AK$5,$F12<=AK$5+6),"◆","") | AL12: =IF(AND($F12>=AL$5,$F12<=AL$5+6),"◆","") | AM12: =IF(AND($F12>=AM$5,$F12<=AM$5+6),"◆","") | AN12: =IF(AND($F12>=AN$5,$F12<=AN$5+6),"◆","") | AO12: =IF(AND($F12>=AO$5,$F12<=AO$5+6),"◆","") | ... BM12: =IF(AND($F12>=BM$5,$F12<=BM$5+6),"◆","")
A13: Planificación | B13: H06 | C13: E3 · fecha tope Acta: 22/01/2027 | D13: Acuerdos de patrocinio firmados – decisión go/no-go financiera | E13: 0 | F13: =MAX($G$81) -> 46409 | G13: =F13 -> 46409 | H13: 3.1.1.6 | I13: Hito de control (duración 0) | J13: {=IF(K13>=1,"Cumplido",IF(FECHA_ESTADO>DATE(2027,1,22),"Atrasado",IF(INDEX(NLAB,MATCH(DATE(2027,1,22),FECHAS,0))-INDEX(NLAB,MATCH(F13,FECHAS,0))<0,"En riesgo","Pendiente")))} -> Pendiente | K13: =IF(MIN($K$81)>=1,1,0) -> 0 | L13: {=INDEX(NLAB,MATCH(DATE(2027,1,22),FECHAS,0))-INDEX(NLAB,MATCH(F13,FECHAS,0))} -> 0 | M13: - | N13: Hito | P13: =IF(AND($F13>=P$5,$F13<=P$5+6),"◆","") | Q13: =IF(AND($F13>=Q$5,$F13<=Q$5+6),"◆","") | R13: =IF(AND($F13>=R$5,$F13<=R$5+6),"◆","") | S13: =IF(AND($F13>=S$5,$F13<=S$5+6),"◆","") | T13: =IF(AND($F13>=T$5,$F13<=T$5+6),"◆","") | U13: =IF(AND($F13>=U$5,$F13<=U$5+6),"◆","") | V13: =IF(AND($F13>=V$5,$F13<=V$5+6),"◆","") | W13: =IF(AND($F13>=W$5,$F13<=W$5+6),"◆","") | ... AG13: =IF(AND($F13>=AG$5,$F13<=AG$5+6),"◆","") | AH13: =IF(AND($F13>=AH$5,$F13<=AH$5+6),"*","") -> * | AI13: =IF(AND($F13>=AI$5,$F13<=AI$5+6),"◆","") | AJ13: =IF(AND($F13>=AJ$5,$F13<=AJ$5+6),"◆","") | AK13: =IF(AND($F13>=AK$5,$F13<=AK$5+6),"◆","") | AL13: =IF(AND($F13>=AL$5,$F13<=AL$5+6),"◆","") | AM13: =IF(AND($F13>=AM$5,$F13<=AM$5+6),"◆","") | AN13: =IF(AND($F13>=AN$5,$F13<=AN$5+6),"◆","") | AO13: =IF(AND($F13>=AO$5,$F13<=AO$5+6),"◆","") | AP13: =IF(AND($F13>=AP$5,$F13<=AP$5+6),"◆","") | ... BM13: =IF(AND($F13>=BM$5,$F13<=BM$5+6),"◆","")
A14: Planificación | B14: H07 | C14: E4 · fecha tope Acta: 05/02/2027 | D14: Programa académico, ponentes, mentores y jurados confirmados | E14: 0 | F14: =MAX($G$114,$G$144,$G$174,$G$122,$G$152,$G$182,$G$205,$G$210,$G$232,$G$239,$G$260,$G$266,$G$289,$G$298) -> 46423 | G14: =F14 -> 46423 | H14: 3.3.2.2, 3.4.2.2, 3.5.2.2, 3.3.4.2, 3.4.4.2, 3.5.4.2, 3.6.2.2, 3.6.3.2, 3.7.2.2, 3.7.4.3, 3.8.2.2, 3.8.3.2, 3.9.2.3, 3.9.4.3 | I14: Hito de control (duración 0) | J14: {=IF(K14>=1,"Cumplido",IF(FECHA_ESTADO>DATE(2027,2,5),"Atrasado",IF(INDEX(NLAB,MATCH(DATE(2027,2,5),FECHAS,0))-INDEX(NLAB,MATCH(F14,FECHAS,0))<0,"En riesgo","Pendiente")))} -> Pendiente | K14: =IF(MIN($K$114,$K$144,$K$174,$K$122,$K$152,$K$182,$K$205,$K$210,$K$232,$K$239,$K$260,$K$266,$K$289,$K$298)>=1,1,0) -> 0 | L14: {=INDEX(NLAB,MATCH(DATE(2027,2,5),FECHAS,0))-INDEX(NLAB,MATCH(F14,FECHAS,0))} -> 0 | M14: - | N14: Hito | P14: =IF(AND($F14>=P$5,$F14<=P$5+6),"◆","") | Q14: =IF(AND($F14>=Q$5,$F14<=Q$5+6),"◆","") | R14: =IF(AND($F14>=R$5,$F14<=R$5+6),"◆","") | S14: =IF(AND($F14>=S$5,$F14<=S$5+6),"◆","") | T14: =IF(AND($F14>=T$5,$F14<=T$5+6),"◆","") | U14: =IF(AND($F14>=U$5,$F14<=U$5+6),"◆","") | V14: =IF(AND($F14>=V$5,$F14<=V$5+6),"◆","") | W14: =IF(AND($F14>=W$5,$F14<=W$5+6),"◆","") | ... AI14: =IF(AND($F14>=AI$5,$F14<=AI$5+6),"◆","") | AJ14: =IF(AND($F14>=AJ$5,$F14<=AJ$5+6),"*","") -> * | AK14: =IF(AND($F14>=AK$5,$F14<=AK$5+6),"◆","") | AL14: =IF(AND($F14>=AL$5,$F14<=AL$5+6),"◆","") | AM14: =IF(AND($F14>=AM$5,$F14<=AM$5+6),"◆","") | AN14: =IF(AND($F14>=AN$5,$F14<=AN$5+6),"◆","") | AO14: =IF(AND($F14>=AO$5,$F14<=AO$5+6),"◆","") | AP14: =IF(AND($F14>=AP$5,$F14<=AP$5+6),"◆","") | AQ14: =IF(AND($F14>=AQ$5,$F14<=AQ$5+6),"◆","") | AR14: =IF(AND($F14>=AR$5,$F14<=AR$5+6),"◆","") | ... BM14: =IF(AND($F14>=BM$5,$F14<=BM$5+6),"◆","")
A15: Planificación | B15: H08 | C15: E5 · fecha tope Acta: 15/02/2027 | D15: Web en producción, lanzamiento de campaña e inscripciones abiertas | E15: 0 | F15: =MAX($G$96) -> 46433 | G15: =F15 -> 46433 | H15: 3.2.1.5 | I15: Hito de control (duración 0) | J15: {=IF(K15>=1,"Cumplido",IF(FECHA_ESTADO>DATE(2027,2,15),"Atrasado",IF(INDEX(NLAB,MATCH(DATE(2027,2,15),FECHAS,0))-INDEX(NLAB,MATCH(F15,FECHAS,0))<0,"En riesgo","Pendiente")))} -> Pendiente | K15: =IF(MIN($K$96)>=1,1,0) -> 0 | L15: {=INDEX(NLAB,MATCH(DATE(2027,2,15),FECHAS,0))-INDEX(NLAB,MATCH(F15,FECHAS,0))} -> 0 | M15: - | N15: Hito | P15: =IF(AND($F15>=P$5,$F15<=P$5+6),"◆","") | Q15: =IF(AND($F15>=Q$5,$F15<=Q$5+6),"◆","") | R15: =IF(AND($F15>=R$5,$F15<=R$5+6),"◆","") | S15: =IF(AND($F15>=S$5,$F15<=S$5+6),"◆","") | T15: =IF(AND($F15>=T$5,$F15<=T$5+6),"◆","") | U15: =IF(AND($F15>=U$5,$F15<=U$5+6),"◆","") | V15: =IF(AND($F15>=V$5,$F15<=V$5+6),"◆","") | W15: =IF(AND($F15>=W$5,$F15<=W$5+6),"◆","") | ... AK15: =IF(AND($F15>=AK$5,$F15<=AK$5+6),"◆","") | AL15: =IF(AND($F15>=AL$5,$F15<=AL$5+6),"*","") -> * | AM15: =IF(AND($F15>=AM$5,$F15<=AM$5+6),"◆","") | AN15: =IF(AND($F15>=AN$5,$F15<=AN$5+6),"◆","") | AO15: =IF(AND($F15>=AO$5,$F15<=AO$5+6),"◆","") | AP15: =IF(AND($F15>=AP$5,$F15<=AP$5+6),"◆","") | AQ15: =IF(AND($F15>=AQ$5,$F15<=AQ$5+6),"◆","") | AR15: =IF(AND($F15>=AR$5,$F15<=AR$5+6),"◆","") | AS15: =IF(AND($F15>=AS$5,$F15<=AS$5+6),"◆","") | AT15: =IF(AND($F15>=AT$5,$F15<=AT$5+6),"◆","") | ... BM15: =IF(AND($F15>=BM$5,$F15<=BM$5+6),"◆","")
A16: Ejecución | B16: H09 | C16: E6 · fecha tope Acta: 04/03/2027 | D16: Inicio del Módulo I (primer taller) | E16: 0 | F16: =MAX($G$124) -> 46450 | G16: =F16 -> 46450 | H16: 3.3.5.1 | I16: Hito de control (duración 0) | J16: {=IF(K16>=1,"Cumplido",IF(FECHA_ESTADO>DATE(2027,3,4),"Atrasado",IF(INDEX(NLAB,MATCH(DATE(2027,3,4),FECHAS,0))-INDEX(NLAB,MATCH(F16,FECHAS,0))<0,"En riesgo","Pendiente")))} -> Pendiente | K16: =IF(MIN($K$124)>=1,1,0) -> 0 | L16: {=INDEX(NLAB,MATCH(DATE(2027,3,4),FECHAS,0))-INDEX(NLAB,MATCH(F16,FECHAS,0))} -> 0 | M16: - | N16: Hito | P16: =IF(AND($F16>=P$5,$F16<=P$5+6),"◆","") | Q16: =IF(AND($F16>=Q$5,$F16<=Q$5+6),"◆","") | R16: =IF(AND($F16>=R$5,$F16<=R$5+6),"◆","") | S16: =IF(AND($F16>=S$5,$F16<=S$5+6),"◆","") | T16: =IF(AND($F16>=T$5,$F16<=T$5+6),"◆","") | U16: =IF(AND($F16>=U$5,$F16<=U$5+6),"◆","") | V16: =IF(AND($F16>=V$5,$F16<=V$5+6),"◆","") | W16: =IF(AND($F16>=W$5,$F16<=W$5+6),"◆","") | ... AM16: =IF(AND($F16>=AM$5,$F16<=AM$5+6),"◆","") | AN16: =IF(AND($F16>=AN$5,$F16<=AN$5+6),"*","") -> * | AO16: =IF(AND($F16>=AO$5,$F16<=AO$5+6),"◆","") | AP16: =IF(AND($F16>=AP$5,$F16<=AP$5+6),"◆","") | AQ16: =IF(AND($F16>=AQ$5,$F16<=AQ$5+6),"◆","") | AR16: =IF(AND($F16>=AR$5,$F16<=AR$5+6),"◆","") | AS16: =IF(AND($F16>=AS$5,$F16<=AS$5+6),"◆","") | AT16: =IF(AND($F16>=AT$5,$F16<=AT$5+6),"◆","") | AU16: =IF(AND($F16>=AU$5,$F16<=AU$5+6),"◆","") | AV16: =IF(AND($F16>=AV$5,$F16<=AV$5+6),"◆","") | ... BM16: =IF(AND($F16>=BM$5,$F16<=BM$5+6),"◆","")
A17: Ejecución | B17: H10 | C17: E6 · fecha tope Acta: 27/03/2027 | D17: Hackathon Kachimbo – cierre del Módulo I | E17: 0 | F17: =MAX($G$216) -> 46473 | G17: =F17 -> 46473 | H17: 3.6.5.1 | I17: Hito de control (duración 0) | J17: {=IF(K17>=1,"Cumplido",IF(FECHA_ESTADO>DATE(2027,3,27),"Atrasado",IF(INDEX(NLAB,MATCH(DATE(2027,3,27),FECHAS,0))-INDEX(NLAB,MATCH(F17,FECHAS,0))<0,"En riesgo","Pendiente")))} -> Pendiente | K17: =IF(MIN($K$216)>=1,1,0) -> 0 | L17: {=INDEX(NLAB,MATCH(DATE(2027,3,27),FECHAS,0))-INDEX(NLAB,MATCH(F17,FECHAS,0))} -> 0 | M17: - | N17: Hito | P17: =IF(AND($F17>=P$5,$F17<=P$5+6),"◆","") | Q17: =IF(AND($F17>=Q$5,$F17<=Q$5+6),"◆","") | R17: =IF(AND($F17>=R$5,$F17<=R$5+6),"◆","") | S17: =IF(AND($F17>=S$5,$F17<=S$5+6),"◆","") | T17: =IF(AND($F17>=T$5,$F17<=T$5+6),"◆","") | U17: =IF(AND($F17>=U$5,$F17<=U$5+6),"◆","") | V17: =IF(AND($F17>=V$5,$F17<=V$5+6),"◆","") | W17: =IF(AND($F17>=W$5,$F17<=W$5+6),"◆","") | ... AP17: =IF(AND($F17>=AP$5,$F17<=AP$5+6),"◆","") | AQ17: =IF(AND($F17>=AQ$5,$F17<=AQ$5+6),"*","") -> * | AR17: =IF(AND($F17>=AR$5,$F17<=AR$5+6),"◆","") | AS17: =IF(AND($F17>=AS$5,$F17<=AS$5+6),"◆","") | AT17: =IF(AND($F17>=AT$5,$F17<=AT$5+6),"◆","") | AU17: =IF(AND($F17>=AU$5,$F17<=AU$5+6),"◆","") | AV17: =IF(AND($F17>=AV$5,$F17<=AV$5+6),"◆","") | AW17: =IF(AND($F17>=AW$5,$F17<=AW$5+6),"◆","") | AX17: =IF(AND($F17>=AX$5,$F17<=AX$5+6),"◆","") | AY17: =IF(AND($F17>=AY$5,$F17<=AY$5+6),"◆","") | ... BM17: =IF(AND($F17>=BM$5,$F17<=BM$5+6),"◆","")
A18: Ejecución | B18: H11 | C18: E7 · fecha tope Acta: 01/04/2027 | D18: Inicio del Módulo II (segundo taller) | E18: 0 | F18: 46478 | G18: 46478 | H18: 3.4.5.1 | I18: Hito de control (duración 0) | J18: {=IF(K18>=1,"Cumplido",IF(FECHA_ESTADO>DATE(2027,4,1),"Atrasado",IF(INDEX(NLAB,MATCH(DATE(2027,4,1),FECHAS,0))-INDEX(NLAB,MATCH(F18,FECHAS,0))<0,"En riesgo","Pendiente")))} -> Pendiente | K18: =IF(MIN($K$216)>=1,1,0) -> 0 | L18: {=INDEX(NLAB,MATCH(DATE(2027,4,1),FECHAS,0))-INDEX(NLAB,MATCH(F18,FECHAS,0))} -> 0 | M18: - | N18: Hito | AQ18: =IF(AND($F18>=AQ$5,$F18<=AQ$5+6),"*","") | AR18: =IF(AND($F18>=AR$5,$F18<=AR$5+6),"*","") -> * | AS18: =IF(AND($F18>=AS$5,$F18<=AS$5+6),"*","") | AT18: =IF(AND($F18>=AT$5,$F18<=AT$5+6),"*","") | AU18: =IF(AND($F18>=AU$5,$F18<=AU$5+6),"*","") | AV18: =IF(AND($F18>=AV$5,$F18<=AV$5+6),"*","") | AW18: =IF(AND($F18>=AW$5,$F18<=AW$5+6),"*","") | AX18: =IF(AND($F18>=AX$5,$F18<=AX$5+6),"*","") | ... BB18: =IF(AND($F18>=BB$5,$F18<=BB$5+6),"*","")
A19: Ejecución | B19: H12 | C19: E7 · fecha tope Acta: 24/04/2027 | D19: Competencia de Kaggle – cierre del Módulo II | E19: 0 | F19: =MAX($G$244) -> 46501 | G19: =F19 -> 46501 | H19: 3.7.6.2 | I19: Hito de control (duración 0) | J19: {=IF(K19>=1,"Cumplido",IF(FECHA_ESTADO>DATE(2027,4,24),"Atrasado",IF(INDEX(NLAB,MATCH(DATE(2027,4,24),FECHAS,0))-INDEX(NLAB,MATCH(F19,FECHAS,0))<0,"En riesgo","Pendiente")))} -> Pendiente | K19: =IF(MIN($K$244)>=1,1,0) -> 0 | L19: {=INDEX(NLAB,MATCH(DATE(2027,4,24),FECHAS,0))-INDEX(NLAB,MATCH(F19,FECHAS,0))} -> 0 | M19: - | N19: Hito | P19: =IF(AND($F19>=P$5,$F19<=P$5+6),"◆","") | Q19: =IF(AND($F19>=Q$5,$F19<=Q$5+6),"◆","") | R19: =IF(AND($F19>=R$5,$F19<=R$5+6),"◆","") | S19: =IF(AND($F19>=S$5,$F19<=S$5+6),"◆","") | T19: =IF(AND($F19>=T$5,$F19<=T$5+6),"◆","") | U19: =IF(AND($F19>=U$5,$F19<=U$5+6),"◆","") | V19: =IF(AND($F19>=V$5,$F19<=V$5+6),"◆","") | W19: =IF(AND($F19>=W$5,$F19<=W$5+6),"◆","") | ... AT19: =IF(AND($F19>=AT$5,$F19<=AT$5+6),"◆","") | AU19: =IF(AND($F19>=AU$5,$F19<=AU$5+6),"*","") -> * | AV19: =IF(AND($F19>=AV$5,$F19<=AV$5+6),"◆","") | AW19: =IF(AND($F19>=AW$5,$F19<=AW$5+6),"◆","") | AX19: =IF(AND($F19>=AX$5,$F19<=AX$5+6),"◆","") | AY19: =IF(AND($F19>=AY$5,$F19<=AY$5+6),"◆","") | AZ19: =IF(AND($F19>=AZ$5,$F19<=AZ$5+6),"◆","") | BA19: =IF(AND($F19>=BA$5,$F19<=BA$5+6),"◆","") | BB19: =IF(AND($F19>=BB$5,$F19<=BB$5+6),"◆","") | BC19: =IF(AND($F19>=BC$5,$F19<=BC$5+6),"◆","") | ... BM19: =IF(AND($F19>=BM$5,$F19<=BM$5+6),"◆","")
A20: Ejecución | B20: H13 | C20: E8 · fecha tope Acta: 29/05/2027 | D20: Hackathon de 8 h "Torneo de Vibecoding" realizado | E20: 0 | F20: =MAX($G$272) -> 46536 | G20: =F20 -> 46536 | H20: 3.8.5.1 | I20: Hito de control (duración 0) | J20: {=IF(K20>=1,"Cumplido",IF(FECHA_ESTADO>DATE(2027,5,29),"Atrasado",IF(INDEX(NLAB,MATCH(DATE(2027,5,29),FECHAS,0))-INDEX(NLAB,MATCH(F20,FECHAS,0))<0,"En riesgo","Pendiente")))} -> Pendiente | K20: =IF(MIN($K$272)>=1,1,0) -> 0 | L20: {=INDEX(NLAB,MATCH(DATE(2027,5,29),FECHAS,0))-INDEX(NLAB,MATCH(F20,FECHAS,0))} -> 0 | M20: - | N20: Hito | P20: =IF(AND($F20>=P$5,$F20<=P$5+6),"◆","") | Q20: =IF(AND($F20>=Q$5,$F20<=Q$5+6),"◆","") | R20: =IF(AND($F20>=R$5,$F20<=R$5+6),"◆","") | S20: =IF(AND($F20>=S$5,$F20<=S$5+6),"◆","") | T20: =IF(AND($F20>=T$5,$F20<=T$5+6),"◆","") | U20: =IF(AND($F20>=U$5,$F20<=U$5+6),"◆","") | V20: =IF(AND($F20>=V$5,$F20<=V$5+6),"◆","") | W20: =IF(AND($F20>=W$5,$F20<=W$5+6),"◆","") | ... AY20: =IF(AND($F20>=AY$5,$F20<=AY$5+6),"◆","") | AZ20: =IF(AND($F20>=AZ$5,$F20<=AZ$5+6),"*","") -> * | BA20: =IF(AND($F20>=BA$5,$F20<=BA$5+6),"◆","") | BB20: =IF(AND($F20>=BB$5,$F20<=BB$5+6),"◆","") | BC20: =IF(AND($F20>=BC$5,$F20<=BC$5+6),"◆","") | BD20: =IF(AND($F20>=BD$5,$F20<=BD$5+6),"◆","") | BE20: =IF(AND($F20>=BE$5,$F20<=BE$5+6),"◆","") | BF20: =IF(AND($F20>=BF$5,$F20<=BF$5+6),"◆","") | BG20: =IF(AND($F20>=BG$5,$F20<=BG$5+6),"◆","") | BH20: =IF(AND($F20>=BH$5,$F20<=BH$5+6),"◆","") | ... BM20: =IF(AND($F20>=BM$5,$F20<=BM$5+6),"◆","")
A21: Ejecución | B21: H14 | C21: E9 · fecha tope Acta: 26/06/2027 | D21: Premiación GCP – cierre del Módulo III | E21: 0 | F21: =MAX($G$191) -> 46564 | G21: =F21 -> 46564 | H21: 3.5.5.8 | I21: Hito de control (duración 0) | J21: {=IF(K21>=1,"Cumplido",IF(FECHA_ESTADO>DATE(2027,6,26),"Atrasado",IF(INDEX(NLAB,MATCH(DATE(2027,6,26),FECHAS,0))-INDEX(NLAB,MATCH(F21,FECHAS,0))<0,"En riesgo","Pendiente")))} -> Pendiente | K21: =IF(MIN($K$191)>=1,1,0) -> 0 | L21: {=INDEX(NLAB,MATCH(DATE(2027,6,26),FECHAS,0))-INDEX(NLAB,MATCH(F21,FECHAS,0))} -> 0 | M21: - | N21: Hito | P21: =IF(AND($F21>=P$5,$F21<=P$5+6),"◆","") | Q21: =IF(AND($F21>=Q$5,$F21<=Q$5+6),"◆","") | R21: =IF(AND($F21>=R$5,$F21<=R$5+6),"◆","") | S21: =IF(AND($F21>=S$5,$F21<=S$5+6),"◆","") | T21: =IF(AND($F21>=T$5,$F21<=T$5+6),"◆","") | U21: =IF(AND($F21>=U$5,$F21<=U$5+6),"◆","") | V21: =IF(AND($F21>=V$5,$F21<=V$5+6),"◆","") | W21: =IF(AND($F21>=W$5,$F21<=W$5+6),"◆","") | ... BC21: =IF(AND($F21>=BC$5,$F21<=BC$5+6),"◆","") | BD21: =IF(AND($F21>=BD$5,$F21<=BD$5+6),"*","") -> * | BE21: =IF(AND($F21>=BE$5,$F21<=BE$5+6),"◆","") | BF21: =IF(AND($F21>=BF$5,$F21<=BF$5+6),"◆","") | BG21: =IF(AND($F21>=BG$5,$F21<=BG$5+6),"◆","") | BH21: =IF(AND($F21>=BH$5,$F21<=BH$5+6),"◆","") | BI21: =IF(AND($F21>=BI$5,$F21<=BI$5+6),"◆","") | BJ21: =IF(AND($F21>=BJ$5,$F21<=BJ$5+6),"◆","") | BK21: =IF(AND($F21>=BK$5,$F21<=BK$5+6),"◆","") | BL21: =IF(AND($F21>=BL$5,$F21<=BL$5+6),"◆","") | BM21: =IF(AND($F21>=BM$5,$F21<=BM$5+6),"◆","")
A22: Ejecución | B22: H15 | C22: E10 · fecha tope Acta: 01/08/2027 | D22: Hackathon Internacional de 24 h realizado (evento cumbre) | E22: 0 | F22: =MAX($G$304) -> 46600 | G22: =F22 -> 46600 | H22: 3.9.6.1 | I22: Hito de control (duración 0) | J22: {=IF(K22>=1,"Cumplido",IF(FECHA_ESTADO>DATE(2027,8,1),"Atrasado",IF(INDEX(NLAB,MATCH(DATE(2027,8,1),FECHAS,0))-INDEX(NLAB,MATCH(F22,FECHAS,0))<0,"En riesgo","Pendiente")))} -> Pendiente | K22: =IF(MIN($K$304)>=1,1,0) -> 0 | L22: {=INDEX(NLAB,MATCH(DATE(2027,8,1),FECHAS,0))-INDEX(NLAB,MATCH(F22,FECHAS,0))} -> 0 | M22: - | N22: Hito | P22: =IF(AND($F22>=P$5,$F22<=P$5+6),"◆","") | Q22: =IF(AND($F22>=Q$5,$F22<=Q$5+6),"◆","") | R22: =IF(AND($F22>=R$5,$F22<=R$5+6),"◆","") | S22: =IF(AND($F22>=S$5,$F22<=S$5+6),"◆","") | T22: =IF(AND($F22>=T$5,$F22<=T$5+6),"◆","") | U22: =IF(AND($F22>=U$5,$F22<=U$5+6),"◆","") | V22: =IF(AND($F22>=V$5,$F22<=V$5+6),"◆","") | W22: =IF(AND($F22>=W$5,$F22<=W$5+6),"◆","") | ... BH22: =IF(AND($F22>=BH$5,$F22<=BH$5+6),"◆","") | BI22: =IF(AND($F22>=BI$5,$F22<=BI$5+6),"*","") -> * | BJ22: =IF(AND($F22>=BJ$5,$F22<=BJ$5+6),"◆","") | BK22: =IF(AND($F22>=BK$5,$F22<=BK$5+6),"◆","") | BL22: =IF(AND($F22>=BL$5,$F22<=BL$5+6),"◆","") | BM22: =IF(AND($F22>=BM$5,$F22<=BM$5+6),"◆","")
A23: Seguimiento y control | B23: H16 | C23: E11 · fecha tope Acta: 02/04/2027 | D23: Reporte de seguimiento N.° 1 presentado (Módulo I y Kachimbo) | E23: 0 | F23: =MAX($G$326) -> 46479 | G23: =F23 -> 46479 | H23: 4.3.4.2 | I23: Hito de control (duración 0) | J23: {=IF(K23>=1,"Cumplido",IF(FECHA_ESTADO>DATE(2027,4,2),"Atrasado",IF(INDEX(NLAB,MATCH(DATE(2027,4,2),FECHAS,0))-INDEX(NLAB,MATCH(F23,FECHAS,0))<0,"En riesgo","Pendiente")))} -> Pendiente | K23: =IF(MIN($K$326)>=1,1,0) -> 0 | L23: {=INDEX(NLAB,MATCH(DATE(2027,4,2),FECHAS,0))-INDEX(NLAB,MATCH(F23,FECHAS,0))} -> 0 | M23: - | N23: Hito | P23: =IF(AND($F23>=P$5,$F23<=P$5+6),"◆","") | Q23: =IF(AND($F23>=Q$5,$F23<=Q$5+6),"◆","") | R23: =IF(AND($F23>=R$5,$F23<=R$5+6),"◆","") | S23: =IF(AND($F23>=S$5,$F23<=S$5+6),"◆","") | T23: =IF(AND($F23>=T$5,$F23<=T$5+6),"◆","") | U23: =IF(AND($F23>=U$5,$F23<=U$5+6),"◆","") | V23: =IF(AND($F23>=V$5,$F23<=V$5+6),"◆","") | W23: =IF(AND($F23>=W$5,$F23<=W$5+6),"◆","") | ... AQ23: =IF(AND($F23>=AQ$5,$F23<=AQ$5+6),"◆","") | AR23: =IF(AND($F23>=AR$5,$F23<=AR$5+6),"*","") -> * | AS23: =IF(AND($F23>=AS$5,$F23<=AS$5+6),"◆","") | AT23: =IF(AND($F23>=AT$5,$F23<=AT$5+6),"◆","") | AU23: =IF(AND($F23>=AU$5,$F23<=AU$5+6),"◆","") | AV23: =IF(AND($F23>=AV$5,$F23<=AV$5+6),"◆","") | AW23: =IF(AND($F23>=AW$5,$F23<=AW$5+6),"◆","") | AX23: =IF(AND($F23>=AX$5,$F23<=AX$5+6),"◆","") | AY23: =IF(AND($F23>=AY$5,$F23<=AY$5+6),"◆","") | AZ23: =IF(AND($F23>=AZ$5,$F23<=AZ$5+6),"◆","") | ... BM23: =IF(AND($F23>=BM$5,$F23<=BM$5+6),"◆","")
A24: Seguimiento y control | B24: H17 | C24: E11 · fecha tope Acta: 30/04/2027 | D24: Reporte de seguimiento N.° 2 presentado (Módulo II y Kaggle) | E24: 0 | F24: =MAX($G$329) -> 46507 | G24: =F24 -> 46507 | H24: 4.3.5.2 | I24: Hito de control (duración 0) | J24: {=IF(K24>=1,"Cumplido",IF(FECHA_ESTADO>DATE(2027,4,30),"Atrasado",IF(INDEX(NLAB,MATCH(DATE(2027,4,30),FECHAS,0))-INDEX(NLAB,MATCH(F24,FECHAS,0))<0,"En riesgo","Pendiente")))} -> Pendiente | K24: =IF(MIN($K$329)>=1,1,0) -> 0 | L24: {=INDEX(NLAB,MATCH(DATE(2027,4,30),FECHAS,0))-INDEX(NLAB,MATCH(F24,FECHAS,0))} -> 0 | M24: - | N24: Hito | P24: =IF(AND($F24>=P$5,$F24<=P$5+6),"◆","") | Q24: =IF(AND($F24>=Q$5,$F24<=Q$5+6),"◆","") | R24: =IF(AND($F24>=R$5,$F24<=R$5+6),"◆","") | S24: =IF(AND($F24>=S$5,$F24<=S$5+6),"◆","") | T24: =IF(AND($F24>=T$5,$F24<=T$5+6),"◆","") | U24: =IF(AND($F24>=U$5,$F24<=U$5+6),"◆","") | V24: =IF(AND($F24>=V$5,$F24<=V$5+6),"◆","") | W24: =IF(AND($F24>=W$5,$F24<=W$5+6),"◆","") | ... AU24: =IF(AND($F24>=AU$5,$F24<=AU$5+6),"◆","") | AV24: =IF(AND($F24>=AV$5,$F24<=AV$5+6),"*","") -> * | AW24: =IF(AND($F24>=AW$5,$F24<=AW$5+6),"◆","") | AX24: =IF(AND($F24>=AX$5,$F24<=AX$5+6),"◆","") | AY24: =IF(AND($F24>=AY$5,$F24<=AY$5+6),"◆","") | AZ24: =IF(AND($F24>=AZ$5,$F24<=AZ$5+6),"◆","") | BA24: =IF(AND($F24>=BA$5,$F24<=BA$5+6),"◆","") | BB24: =IF(AND($F24>=BB$5,$F24<=BB$5+6),"◆","") | BC24: =IF(AND($F24>=BC$5,$F24<=BC$5+6),"◆","") | BD24: =IF(AND($F24>=BD$5,$F24<=BD$5+6),"◆","") | ... BM24: =IF(AND($F24>=BM$5,$F24<=BM$5+6),"◆","")
A25: Seguimiento y control | B25: H18 | C25: E11 · fecha tope Acta: 04/06/2027 | D25: Reporte de seguimiento N.° 3 presentado (Torneo de Vibecoding) | E25: 0 | F25: =MAX($G$332) -> 46542 | G25: =F25 -> 46542 | H25: 4.3.6.2 | I25: Hito de control (duración 0) | J25: {=IF(K25>=1,"Cumplido",IF(FECHA_ESTADO>DATE(2027,6,4),"Atrasado",IF(INDEX(NLAB,MATCH(DATE(2027,6,4),FECHAS,0))-INDEX(NLAB,MATCH(F25,FECHAS,0))<0,"En riesgo","Pendiente")))} -> Pendiente | K25: =IF(MIN($K$332)>=1,1,0) -> 0 | L25: {=INDEX(NLAB,MATCH(DATE(2027,6,4),FECHAS,0))-INDEX(NLAB,MATCH(F25,FECHAS,0))} -> 0 | M25: - | N25: Hito | P25: =IF(AND($F25>=P$5,$F25<=P$5+6),"◆","") | Q25: =IF(AND($F25>=Q$5,$F25<=Q$5+6),"◆","") | R25: =IF(AND($F25>=R$5,$F25<=R$5+6),"◆","") | S25: =IF(AND($F25>=S$5,$F25<=S$5+6),"◆","") | T25: =IF(AND($F25>=T$5,$F25<=T$5+6),"◆","") | U25: =IF(AND($F25>=U$5,$F25<=U$5+6),"◆","") | V25: =IF(AND($F25>=V$5,$F25<=V$5+6),"◆","") | W25: =IF(AND($F25>=W$5,$F25<=W$5+6),"◆","") | ... AZ25: =IF(AND($F25>=AZ$5,$F25<=AZ$5+6),"◆","") | BA25: =IF(AND($F25>=BA$5,$F25<=BA$5+6),"*","") -> * | BB25: =IF(AND($F25>=BB$5,$F25<=BB$5+6),"◆","") | BC25: =IF(AND($F25>=BC$5,$F25<=BC$5+6),"◆","") | BD25: =IF(AND($F25>=BD$5,$F25<=BD$5+6),"◆","") | BE25: =IF(AND($F25>=BE$5,$F25<=BE$5+6),"◆","") | BF25: =IF(AND($F25>=BF$5,$F25<=BF$5+6),"◆","") | BG25: =IF(AND($F25>=BG$5,$F25<=BG$5+6),"◆","") | BH25: =IF(AND($F25>=BH$5,$F25<=BH$5+6),"◆","") | BI25: =IF(AND($F25>=BI$5,$F25<=BI$5+6),"◆","") | ... BM25: =IF(AND($F25>=BM$5,$F25<=BM$5+6),"◆","")
A26: Seguimiento y control | B26: H19 | C26: E11 · fecha tope Acta: 02/07/2027 | D26: Reporte de seguimiento N.° 4 presentado (Módulo III y premiación GCP) | E26: 0 | F26: =MAX($G$323) -> 46570 | G26: =F26 -> 46570 | H26: 4.3.3.2 | I26: Hito de control (duración 0) | J26: {=IF(K26>=1,"Cumplido",IF(FECHA_ESTADO>DATE(2027,7,2),"Atrasado",IF(INDEX(NLAB,MATCH(DATE(2027,7,2),FECHAS,0))-INDEX(NLAB,MATCH(F26,FECHAS,0))<0,"En riesgo","Pendiente")))} -> Pendiente | K26: =IF(MIN($K$323)>=1,1,0) -> 0 | L26: {=INDEX(NLAB,MATCH(DATE(2027,7,2),FECHAS,0))-INDEX(NLAB,MATCH(F26,FECHAS,0))} -> 0 | M26: - | N26: Hito | P26: =IF(AND($F26>=P$5,$F26<=P$5+6),"◆","") | Q26: =IF(AND($F26>=Q$5,$F26<=Q$5+6),"◆","") | R26: =IF(AND($F26>=R$5,$F26<=R$5+6),"◆","") | S26: =IF(AND($F26>=S$5,$F26<=S$5+6),"◆","") | T26: =IF(AND($F26>=T$5,$F26<=T$5+6),"◆","") | U26: =IF(AND($F26>=U$5,$F26<=U$5+6),"◆","") | V26: =IF(AND($F26>=V$5,$F26<=V$5+6),"◆","") | W26: =IF(AND($F26>=W$5,$F26<=W$5+6),"◆","") | ... BD26: =IF(AND($F26>=BD$5,$F26<=BD$5+6),"◆","") | BE26: =IF(AND($F26>=BE$5,$F26<=BE$5+6),"*","") -> * | BF26: =IF(AND($F26>=BF$5,$F26<=BF$5+6),"◆","") | BG26: =IF(AND($F26>=BG$5,$F26<=BG$5+6),"◆","") | BH26: =IF(AND($F26>=BH$5,$F26<=BH$5+6),"◆","") | BI26: =IF(AND($F26>=BI$5,$F26<=BI$5+6),"◆","") | BJ26: =IF(AND($F26>=BJ$5,$F26<=BJ$5+6),"◆","") | BK26: =IF(AND($F26>=BK$5,$F26<=BK$5+6),"◆","") | BL26: =IF(AND($F26>=BL$5,$F26<=BL$5+6),"◆","") | BM26: =IF(AND($F26>=BM$5,$F26<=BM$5+6),"◆","")
A27: Seguimiento y control | B27: H20 | C27: E11 · fecha tope Acta: 05/08/2027 | D27: Reporte de seguimiento N.° 5 presentado (Hackathon de 24 h) | E27: 0 | F27: =MAX($G$335) -> 46604 | G27: =F27 -> 46604 | H27: 4.3.7.2 | I27: Hito de control (duración 0) | J27: {=IF(K27>=1,"Cumplido",IF(FECHA_ESTADO>DATE(2027,8,5),"Atrasado",IF(INDEX(NLAB,MATCH(DATE(2027,8,5),FECHAS,0))-INDEX(NLAB,MATCH(F27,FECHAS,0))<0,"En riesgo","Pendiente")))} -> Pendiente | K27: =IF(MIN($K$335)>=1,1,0) -> 0 | L27: {=INDEX(NLAB,MATCH(DATE(2027,8,5),FECHAS,0))-INDEX(NLAB,MATCH(F27,FECHAS,0))} -> 0 | M27: - | N27: Hito | P27: =IF(AND($F27>=P$5,$F27<=P$5+6),"◆","") | Q27: =IF(AND($F27>=Q$5,$F27<=Q$5+6),"◆","") | R27: =IF(AND($F27>=R$5,$F27<=R$5+6),"◆","") | S27: =IF(AND($F27>=S$5,$F27<=S$5+6),"◆","") | T27: =IF(AND($F27>=T$5,$F27<=T$5+6),"◆","") | U27: =IF(AND($F27>=U$5,$F27<=U$5+6),"◆","") | V27: =IF(AND($F27>=V$5,$F27<=V$5+6),"◆","") | W27: =IF(AND($F27>=W$5,$F27<=W$5+6),"◆","") | ... BI27: =IF(AND($F27>=BI$5,$F27<=BI$5+6),"◆","") | BJ27: =IF(AND($F27>=BJ$5,$F27<=BJ$5+6),"*","") -> * | BK27: =IF(AND($F27>=BK$5,$F27<=BK$5+6),"◆","") | BL27: =IF(AND($F27>=BL$5,$F27<=BL$5+6),"◆","") | BM27: =IF(AND($F27>=BM$5,$F27<=BM$5+6),"◆","")
A28: Cierre | B28: H21 | C28: E12 · fecha tope Acta: 13/08/2027 | D28: Informe final de resultados aprobado y enviado a sponsors y PUCP | E28: 0 | F28: =MAX($G$339) -> 46612 | G28: =F28 -> 46612 | H28: 5.1.2 | I28: Hito de control (duración 0) | J28: {=IF(K28>=1,"Cumplido",IF(FECHA_ESTADO>DATE(2027,8,13),"Atrasado",IF(INDEX(NLAB,MATCH(DATE(2027,8,13),FECHAS,0))-INDEX(NLAB,MATCH(F28,FECHAS,0))<0,"En riesgo","Pendiente")))} -> Pendiente | K28: =IF(MIN($K$339)>=1,1,0) -> 0 | L28: {=INDEX(NLAB,MATCH(DATE(2027,8,13),FECHAS,0))-INDEX(NLAB,MATCH(F28,FECHAS,0))} -> 0 | M28: - | N28: Hito | P28: =IF(AND($F28>=P$5,$F28<=P$5+6),"◆","") | Q28: =IF(AND($F28>=Q$5,$F28<=Q$5+6),"◆","") | R28: =IF(AND($F28>=R$5,$F28<=R$5+6),"◆","") | S28: =IF(AND($F28>=S$5,$F28<=S$5+6),"◆","") | T28: =IF(AND($F28>=T$5,$F28<=T$5+6),"◆","") | U28: =IF(AND($F28>=U$5,$F28<=U$5+6),"◆","") | V28: =IF(AND($F28>=V$5,$F28<=V$5+6),"◆","") | W28: =IF(AND($F28>=W$5,$F28<=W$5+6),"◆","") | ... AB28: =IF(AND($F28>=AB$5,$F28<=AB$5+6),"◆","") | AC28: =IF(AND($F28>=AC$5,$F28<=AC$5+6),"*","") | AD28: =IF(AND($F28>=AD$5,$F28<=AD$5+6),"*","") | AE28: =IF(AND($F28>=AE$5,$F28<=AE$5+6),"*","") | AF28: =IF(AND($F28>=AF$5,$F28<=AF$5+6),"*","") | AG28: =IF(AND($F28>=AG$5,$F28<=AG$5+6),"*","") | AH28: =IF(AND($F28>=AH$5,$F28<=AH$5+6),"*","") | AI28: =IF(AND($F28>=AI$5,$F28<=AI$5+6),"*","") | AJ28: =IF(AND($F28>=AJ$5,$F28<=AJ$5+6),"*","") | ... BK28: =IF(AND($F28>=BK$5,$F28<=BK$5+6),"*","") -> * | BL28: =IF(AND($F28>=BL$5,$F28<=BL$5+6),"◆","") | BM28: =IF(AND($F28>=BM$5,$F28<=BM$5+6),"◆","")
A29: Cierre | B29: H22 | C29: E13 · fecha tope Acta: 20/08/2027 | D29: Acta de cierre firmada – fin del proyecto | E29: 0 | F29: =MAX($G$350) -> 46619 | G29: =F29 -> 46619 | H29: 5.4.3 | I29: Hito de control (duración 0) | J29: {=IF(K29>=1,"Cumplido",IF(FECHA_ESTADO>DATE(2027,8,20),"Atrasado",IF(INDEX(NLAB,MATCH(DATE(2027,8,20),FECHAS,0))-INDEX(NLAB,MATCH(F29,FECHAS,0))<0,"En riesgo","Pendiente")))} -> Pendiente | K29: =IF(MIN($K$350)>=1,1,0) -> 0 | L29: {=INDEX(NLAB,MATCH(DATE(2027,8,20),FECHAS,0))-INDEX(NLAB,MATCH(F29,FECHAS,0))} -> 0 | M29: - | N29: Hito | P29: =IF(AND($F29>=P$5,$F29<=P$5+6),"◆","") | Q29: =IF(AND($F29>=Q$5,$F29<=Q$5+6),"◆","") | R29: =IF(AND($F29>=R$5,$F29<=R$5+6),"◆","") | S29: =IF(AND($F29>=S$5,$F29<=S$5+6),"◆","") | T29: =IF(AND($F29>=T$5,$F29<=T$5+6),"◆","") | U29: =IF(AND($F29>=U$5,$F29<=U$5+6),"◆","") | V29: =IF(AND($F29>=V$5,$F29<=V$5+6),"◆","") | W29: =IF(AND($F29>=W$5,$F29<=W$5+6),"◆","") | ... BK29: =IF(AND($F29>=BK$5,$F29<=BK$5+6),"◆","") | BL29: =IF(AND($F29>=BL$5,$F29<=BL$5+6),"*","") -> * | BM29: =IF(AND($F29>=BM$5,$F29<=BM$5+6),"◆","")
A30: Inicio | B30: 1 | C30: INICIO | E30: {=INDEX(NLAB,MATCH(G30,FECHAS,0))-INDEX(NLAB,MATCH(F30,FECHAS,0))+1} -> 29 | F30: =MIN(F31:F42) -> 46279 | G30: =MAX(G31:G42) -> 46312 | J30: =IF(K30>=1,"Completado",IF(AND(G30<FECHA_ESTADO,K30<1),"Atrasado",IF(K30>0,"En progreso","No iniciado"))) -> En progreso | K30: =IFERROR(SUMPRODUCT(--(C31:C42=""),E31:E42,K31:K42)/SUMPRODUCT(--(C31:C42=""),E31:E42),0) -> 0.39473684
A31: Inicio | B31: 1.1 | C31: Acta de constitución del proyecto | E31: {=INDEX(NLAB,MATCH(G31,FECHAS,0))-INDEX(NLAB,MATCH(F31,FECHAS,0))+1} -> 1 | F31: =MIN(F32) -> 46279 | G31: =MAX(G32) -> 46279 | J31: =IF(K31>=1,"Completado",IF(AND(G31<FECHA_ESTADO,K31<1),"Atrasado",IF(K31>0,"En progreso","No iniciado"))) -> Completado | K31: =IFERROR(SUMPRODUCT(--(C32=""),E32,K32)/SUMPRODUCT(--(C32=""),E32),0) -> 1
A32: Inicio | B32: 1.1.1 | D32: Revisar, aprobar y firmar el Acta de Constitución y designar al Gerente de Proyecto | E32: 1 | F32: 46279 | G32: {=IF(E32=0,F32,INDEX(FECHAS,MATCH(INDEX(NLAB,MATCH(F32,FECHAS,0))+E32-1,NLAB,0)))} -> 46279 | H32: Ninguna | I32: Patrocinador (L. Flores); Gerente de Proyecto (L. Alvites) | J32: =IF(K32>=1,"Completado",IF(G32<FECHA_ESTADO,"Atrasado",IF(K32>0,"En progreso","No iniciado"))) -> Completado | K32: 1 | L32: {=MIN(INDEX(NLAB,MATCH($F$34,FECHAS,0))-1,INDEX(NLAB,MATCH($F$41,FECHAS,0))-1,INDEX(NLAB,MATCH($F$59,FECHAS,0))-1,INDEX(NLAB,MATCH(DATE(2026,9,14),FECHAS,0)))-INDEX(NLAB,MATCH(G32,FECHAS,0))} -> 0 | M32: 0 | N32: =IF(M32<=0,"Sí","No") -> Sí
A33: Inicio | B33: 1.2 | C33: Declaración preliminar del alcance | E33: {=INDEX(NLAB,MATCH(G33,FECHAS,0))-INDEX(NLAB,MATCH(F33,FECHAS,0))+1} -> 4 | F33: =MIN(F34:F35) -> 46280 | G33: =MAX(G34:G35) -> 46283 | J33: =IF(K33>=1,"Completado",IF(AND(G33<FECHA_ESTADO,K33<1),"Atrasado",IF(K33>0,"En progreso","No iniciado"))) -> Completado | K33: =IFERROR(SUMPRODUCT(--(C34:C35=""),E34:E35,K34:K35)/SUMPRODUCT(--(C34:C35=""),E34:E35),0) -> 1
A34: Inicio | B34: 1.2.1 | D34: Definir inclusiones, exclusiones y supuestos del programa | E34: 3 | F34: {=INDEX(FECHAS,MATCH(INDEX(NLAB,MATCH($G$32,FECHAS,0))+1,NLAB,0))} -> 46280 | G34: {=IF(E34=0,F34,INDEX(FECHAS,MATCH(INDEX(NLAB,MATCH(F34,FECHAS,0))+E34-1,NLAB,0)))} -> 46282 | H34: 1.1.1 | I34: Equipo 5 (Planificación) | J34: =IF(K34>=1,"Completado",IF(G34<FECHA_ESTADO,"Atrasado",IF(K34>0,"En progreso","No iniciado"))) -> Completado | K34: 1 | L34: {=INDEX(NLAB,MATCH($F$35,FECHAS,0))-1-INDEX(NLAB,MATCH(G34,FECHAS,0))} -> 0 | M34: 1 | N34: =IF(M34<=0,"Sí","No") -> No
A35: Inicio | B35: 1.2.2 | D35: Validar el alcance preliminar con el Patrocinador | E35: 1 | F35: {=INDEX(FECHAS,MATCH(INDEX(NLAB,MATCH($G$34,FECHAS,0))+1,NLAB,0))} -> 46283 | G35: {=IF(E35=0,F35,INDEX(FECHAS,MATCH(INDEX(NLAB,MATCH(F35,FECHAS,0))+E35-1,NLAB,0)))} -> 46283 | H35: 1.2.1 | I35: Gerente de Proyecto (L. Alvites); Patrocinador (L. Flores) | J35: =IF(K35>=1,"Completado",IF(G35<FECHA_ESTADO,"Atrasado",IF(K35>0,"En progreso","No iniciado"))) -> Completado | K35: 1 | L35: {=INDEX(NLAB,MATCH($F$42,FECHAS,0))-1-INDEX(NLAB,MATCH(G35,FECHAS,0))} -> 1 | M35: 1 | N35: =IF(M35<=0,"Sí","No") -> No
A36: Inicio | B36: 1.3 | C36: Acuerdos iniciales con patrocinadores | E36: {=INDEX(NLAB,MATCH(G36,FECHAS,0))-INDEX(NLAB,MATCH(F36,FECHAS,0))+1} -> 22 | F36: =MIN(F37:F39) -> 46287 | G36: =MAX(G37:G39) -> 46312 | J36: =IF(K36>=1,"Completado",IF(AND(G36<FECHA_ESTADO,K36<1),"Atrasado",IF(K36>0,"En progreso","No iniciado"))) -> En progreso | K36: =IFERROR(SUMPRODUCT(--(C37:C39=""),E37:E39,K37:K39)/SUMPRODUCT(--(C37:C39=""),E37:E39),0) -> 0.17857143
A37: Inicio | B37: 1.3.1 | D37: Identificar y priorizar empresas potenciales (base de datos de sponsors) | E37: 10 | F37: {=INDEX(FECHAS,MATCH(INDEX(NLAB,MATCH($G$42,FECHAS,0))+1,NLAB,0))} -> 46287 | G37: {=IF(E37=0,F37,INDEX(FECHAS,MATCH(INDEX(NLAB,MATCH(F37,FECHAS,0))+E37-1,NLAB,0)))} -> 46297 | H37: 1.4.2 | I37: Relaciones Exteriores (S. Cruz) | J37: =IF(K37>=1,"Completado",IF(G37<FECHA_ESTADO,"Atrasado",IF(K37>0,"En progreso","No iniciado"))) -> En progreso | K37: 0.5 | L37: {=MIN(INDEX(NLAB,MATCH($F$38,FECHAS,0))-1,INDEX(NLAB,MATCH($F$39,FECHAS,0))-1,INDEX(NLAB,MATCH($F$77,FECHAS,0))-1)-INDEX(NLAB,MATCH(G37,FECHAS,0))} -> 0 | M37: 28 | N37: =IF(M37<=0,"Sí","No") -> No
A38: Inicio | B38: 1.3.2 | D38: Obtener carta de intención de NTT Data Perú como sede del evento final | E38: 12 | F38: {=INDEX(FECHAS,MATCH(INDEX(NLAB,MATCH($G$37,FECHAS,0))+1,NLAB,0))} -> 46298 | G38: {=IF(E38=0,F38,INDEX(FECHAS,MATCH(INDEX(NLAB,MATCH(F38,FECHAS,0))+E38-1,NLAB,0)))} -> 46312 | H38: 1.3.1 | I38: Relaciones Exteriores (S. Cruz); Gerente de Proyecto (L. Alvites) | J38: =IF(K38>=1,"Completado",IF(G38<FECHA_ESTADO,"Atrasado",IF(K38>0,"En progreso","No iniciado"))) -> No iniciado | K38: 0 | L38: {=INDEX(NLAB,MATCH($F$79,FECHAS,0))-1-INDEX(NLAB,MATCH(G38,FECHAS,0))} -> 17 | M38: 52 | N38: =IF(M38<=0,"Sí","No") -> No
A39: Inicio | B39: 1.3.3 | D39: Confirmar con el programa de Google para comunidades los créditos GCP | E39: 6 | F39: {=INDEX(FECHAS,MATCH(INDEX(NLAB,MATCH($G$37,FECHAS,0))+1,NLAB,0))} -> 46298 | G39: {=IF(E39=0,F39,INDEX(FECHAS,MATCH(INDEX(NLAB,MATCH(F39,FECHAS,0))+E39-1,NLAB,0)))} -> 46305 | H39: 1.3.1 | I39: Relaciones Exteriores (S. Cruz) | J39: =IF(K39>=1,"Completado",IF(G39<FECHA_ESTADO,"Atrasado",IF(K39>0,"En progreso","No iniciado"))) -> No iniciado | K39: 0 | L39: {=INDEX(NLAB,MATCH($F$181,FECHAS,0))-1-INDEX(NLAB,MATCH(G39,FECHAS,0))} -> 80 | M39: 89 | N39: =IF(M39<=0,"Sí","No") -> No
A40: Inicio | B40: 1.4 | C40: Registro de interesados | E40: {=INDEX(NLAB,MATCH(G40,FECHAS,0))-INDEX(NLAB,MATCH(F40,FECHAS,0))+1} -> 6 | F40: =MIN(F41:F42) -> 46280 | G40: =MAX(G41:G42) -> 46286 | J40: =IF(K40>=1,"Completado",IF(AND(G40<FECHA_ESTADO,K40<1),"Atrasado",IF(K40>0,"En progreso","No iniciado"))) -> Completado | K40: =IFERROR(SUMPRODUCT(--(C41:C42=""),E41:E42,K41:K42)/SUMPRODUCT(--(C41:C42=""),E41:E42),0) -> 1
...

Sheet Calendario
A1: Calendario laboral del proyecto (lunes a sábado; domingos y feriados nacionales no laborables)
A3: Inicio del proyecto | B3: 46279
A4: Fin del proyecto (acta de cierre) | B4: 46619
A5: Fecha de estado (corte del avance) | B5: 46291 | C5: ← actualizar en cada reunión semanal de seguimiento
A7: FECHA | B7: DÍA | C7: LABORABLE (1 = sí) | D7: N.° DÍA LABORABLE | F7: FERIADO | G7: DESCRIPCIÓN
A8: 46272 | B8: =CHOOSE(WEEKDAY(A8),"dom","lun","mar","mié","jue","vie","sáb") -> lun | C8: =IF(OR(WEEKDAY(A8)=1,COUNTIF(FERIADOS,A8)>0),0,1) -> 1 | D8: =C8 -> 1 | F8: 46303 | G8: Combate de Angamos
A9: =A8+1 -> 46273 | B9: =CHOOSE(WEEKDAY(A9),"dom","lun","mar","mié","jue","vie","sáb") -> mar | C9: =IF(OR(WEEKDAY(A9)=1,COUNTIF(FERIADOS,A9)>0),0,1) -> 1 | D9: =D8+C9 -> 2 | F9: 46327 | G9: Día de Todos los Santos
A10: =A9+1 -> 46274 | B10: =CHOOSE(WEEKDAY(A10),"dom","lun","mar","mié","jue","vie","sáb") -> mié | C10: =IF(OR(WEEKDAY(A10)=1,COUNTIF(FERIADOS,A10)>0),0,1) -> 1 | D10: =D9+C10 -> 3 | F10: 46364 | G10: Inmaculada Concepción
A11: =A10+1 -> 46275 | B11: =CHOOSE(WEEKDAY(A11),"dom","lun","mar","mié","jue","vie","sáb") -> jue | C11: =IF(OR(WEEKDAY(A11)=1,COUNTIF(FERIADOS,A11)>0),0,1) -> 1 | D11: =D10+C11 -> 4 | F11: 46365 | G11: Batalla de Ayacucho
A12: =A11+1 -> 46276 | B12: =CHOOSE(WEEKDAY(A12),"dom","lun","mar","mié","jue","vie","sáb") -> vie | C12: =IF(OR(WEEKDAY(A12)=1,COUNTIF(FERIADOS,A12)>0),0,1) -> 1 | D12: =D11+C12 -> 5 | F12: 46381 | G12: Navidad
A13: =A12+1 -> 46277 | B13: =CHOOSE(WEEKDAY(A13),"dom","lun","mar","mié","jue","vie","sáb") -> sáb | C13: =IF(OR(WEEKDAY(A13)=1,COUNTIF(FERIADOS,A13)>0),0,1) -> 1 | D13: =D12+C13 -> 6 | F13: 46388 | G13: Año Nuevo
A14: =A13+1 -> 46278 | B14: =CHOOSE(WEEKDAY(A14),"dom","lun","mar","mié","jue","vie","sáb") -> dom | C14: =IF(OR(WEEKDAY(A14)=1,COUNTIF(FERIADOS,A14)>0),0,1) -> 0 | D14: =D13+C14 -> 6 | F14: 46471 | G14: Jueves Santo
A15: =A14+1 -> 46279 | B15: =CHOOSE(WEEKDAY(A15),"dom","lun","mar","mié","jue","vie","sáb") -> lun | C15: =IF(OR(WEEKDAY(A15)=1,COUNTIF(FERIADOS,A15)>0),0,1) -> 1 | D15: =D14+C15 -> 7 | F15: 46472 | G15: Viernes Santo
A16: =A15+1 -> 46280 | B16: =CHOOSE(WEEKDAY(A16),"dom","lun","mar","mié","jue","vie","sáb") -> mar | C16: =IF(OR(WEEKDAY(A16)=1,COUNTIF(FERIADOS,A16)>0),0,1) -> 1 | D16: =D15+C16 -> 8 | F16: 46508 | G16: Día del Trabajo
A17: =A16+1 -> 46281 | B17: =CHOOSE(WEEKDAY(A17),"dom","lun","mar","mié","jue","vie","sáb") -> mié | C17: =IF(OR(WEEKDAY(A17)=1,COUNTIF(FERIADOS,A17)>0),0,1) -> 1 | D17: =D16+C17 -> 9 | F17: 46545 | G17: Batalla de Arica y Día de la Bandera
A18: =A17+1 -> 46282 | B18: =CHOOSE(WEEKDAY(A18),"dom","lun","mar","mié","jue","vie","sáb") -> jue | C18: =IF(OR(WEEKDAY(A18)=1,COUNTIF(FERIADOS,A18)>0),0,1) -> 1 | D18: =D17+C18 -> 10 | F18: 46567 | G18: San Pedro y San Pablo
A19: =A18+1 -> 46283 | B19: =CHOOSE(WEEKDAY(A19),"dom","lun","mar","mié","jue","vie","sáb") -> vie | C19: =IF(OR(WEEKDAY(A19)=1,COUNTIF(FERIADOS,A19)>0),0,1) -> 1 | D19: =D18+C19 -> 11 | F19: 46591 | G19: Día de la Fuerza Aérea del Perú
A20: =A19+1 -> 46284 | B20: =CHOOSE(WEEKDAY(A20),"dom","lun","mar","mié","jue","vie","sáb") -> sáb | C20: =IF(OR(WEEKDAY(A20)=1,COUNTIF(FERIADOS,A20)>0),0,1) -> 1 | D20: =D19+C20 -> 12 | F20: 46596 | G20: Fiestas Patrias
... A23: =A22+1 -> 46287 | B23: =CHOOSE(WEEKDAY(A23),"dom","lun","mar","mié","jue","vie","sáb") -> mar | C23: =IF(OR(WEEKDAY(A23)=1,COUNTIF(FERIADOS,A23)>0),0,1) -> 1 | D23: =D22+C23 -> 14 | F23: 46629 | G23: Santa Rosa de Lima
A24: =A23+1 -> 46288 | B24: =CHOOSE(WEEKDAY(A24),"dom","lun","mar","mié","jue","vie","sáb") -> mié | C24: =IF(OR(WEEKDAY(A24)=1,COUNTIF(FERIADOS,A24)>0),0,1) -> 1 | D24: =D23+C24 -> 15
A25: =A24+1 -> 46289 | B25: =CHOOSE(WEEKDAY(A25),"dom","lun","mar","mié","jue","vie","sáb") -> jue | C25: =IF(OR(WEEKDAY(A25)=1,COUNTIF(FERIADOS,A25)>0),0,1) -> 1 | D25: =D24+C25 -> 16
A26: =A25+1 -> 46290 | B26: =CHOOSE(WEEKDAY(A26),"dom","lun","mar","mié","jue","vie","sáb") -> vie | C26: =IF(OR(WEEKDAY(A26)=1,COUNTIF(FERIADOS,A26)>0),0,1) -> 1 | D26: =D25+C26 -> 17
A27: =A26+1 -> 46291 | B27: =CHOOSE(WEEKDAY(A27),"dom","lun","mar","mié","jue","vie","sáb") -> sáb | C27: =IF(OR(WEEKDAY(A27)=1,COUNTIF(FERIADOS,A27)>0),0,1) -> 1 | D27: =D26+C27 -> 18
A28: =A27+1 -> 46292 | B28: =CHOOSE(WEEKDAY(A28),"dom","lun","mar","mié","jue","vie","sáb") -> dom | C28: =IF(OR(WEEKDAY(A28)=1,COUNTIF(FERIADOS,A28)>0),0,1) -> 0 | D28: =D27+C28 -> 18
A29: =A28+1 -> 46293 | B29: =CHOOSE(WEEKDAY(A29),"dom","lun","mar","mié","jue","vie","sáb") -> lun | C29: =IF(OR(WEEKDAY(A29)=1,COUNTIF(FERIADOS,A29)>0),0,1) -> 1 | D29: =D28+C29 -> 19
A30: =A29+1 -> 46294 | B30: =CHOOSE(WEEKDAY(A30),"dom","lun","mar","mié","jue","vie","sáb") -> mar | C30: =IF(OR(WEEKDAY(A30)=1,COUNTIF(FERIADOS,A30)>0),0,1) -> 1 | D30: =D29+C30 -> 20
A31: =A30+1 -> 46295 | B31: =CHOOSE(WEEKDAY(A31),"dom","lun","mar","mié","jue","vie","sáb") -> mié | C31: =IF(OR(WEEKDAY(A31)=1,COUNTIF(FERIADOS,A31)>0),0,1) -> 1 | D31: =D30+C31 -> 21
A32: =A31+1 -> 46296 | B32: =CHOOSE(WEEKDAY(A32),"dom","lun","mar","mié","jue","vie","sáb") -> jue | C32: =IF(OR(WEEKDAY(A32)=1,COUNTIF(FERIADOS,A32)>0),0,1) -> 1 | D32: =D31+C32 -> 22
A33: =A32+1 -> 46297 | B33: =CHOOSE(WEEKDAY(A33),"dom","lun","mar","mié","jue","vie","sáb") -> vie | C33: =IF(OR(WEEKDAY(A33)=1,COUNTIF(FERIADOS,A33)>0),0,1) -> 1 | D33: =D32+C33 -> 23
A34: =A33+1 -> 46298 | B34: =CHOOSE(WEEKDAY(A34),"dom","lun","mar","mié","jue","vie","sáb") -> sáb | C34: =IF(OR(WEEKDAY(A34)=1,COUNTIF(FERIADOS,A34)>0),0,1) -> 1 | D34: =D33+C34 -> 24
A35: =A34+1 -> 46299 | B35: =CHOOSE(WEEKDAY(A35),"dom","lun","mar","mié","jue","vie","sáb") -> dom | C35: =IF(OR(WEEKDAY(A35)=1,COUNTIF(FERIADOS,A35)>0),0,1) -> 0 | D35: =D34+C35 -> 24
... A37: =A36+1 -> 46301 | B37: =CHOOSE(WEEKDAY(A37),"dom","lun","mar","mié","jue","vie","sáb") -> mar | C37: =IF(OR(WEEKDAY(A37)=1,COUNTIF(FERIADOS,A37)>0),0,1) -> 1 | D37: =D36+C37 -> 26
A38: =A37+1 -> 46302 | B38: =CHOOSE(WEEKDAY(A38),"dom","lun","mar","mié","jue","vie","sáb") -> mié | C38: =IF(OR(WEEKDAY(A38)=1,COUNTIF(FERIADOS,A38)>0),0,1) -> 1 | D38: =D37+C38 -> 27 | F38: Agregar feriados o días no laborables adicionales (p. ej., cierre de campus) en las filas en blanco de la lista; el cronograma se recalcula solo.
A39: =A38+1 -> 46303 | B39: =CHOOSE(WEEKDAY(A39),"dom","lun","mar","mié","jue","vie","sáb") -> jue | C39: =IF(OR(WEEKDAY(A39)=1,COUNTIF(FERIADOS,A39)>0),0,1) -> 0 | D39: =D38+C39 -> 27
A40: =A39+1 -> 46304 | B40: =CHOOSE(WEEKDAY(A40),"dom","lun","mar","mié","jue","vie","sáb") -> vie | C40: =IF(OR(WEEKDAY(A40)=1,COUNTIF(FERIADOS,A40)>0),0,1) -> 1 | D40: =D39+C40 -> 28
A41: =A40+1 -> 46305 | B41: =CHOOSE(WEEKDAY(A41),"dom","lun","mar","mié","jue","vie","sáb") -> sáb | C41: =IF(OR(WEEKDAY(A41)=1,COUNTIF(FERIADOS,A41)>0),0,1) -> 1 | D41: =D40+C41 -> 29
A42: =A41+1 -> 46306 | B42: =CHOOSE(WEEKDAY(A42),"dom","lun","mar","mié","jue","vie","sáb") -> dom | C42: =IF(OR(WEEKDAY(A42)=1,COUNTIF(FERIADOS,A42)>0),0,1) -> 0 | D42: =D41+C42 -> 29
A43: =A42+1 -> 46307 | B43: =CHOOSE(WEEKDAY(A43),"dom","lun","mar","mié","jue","vie","sáb") -> lun | C43: =IF(OR(WEEKDAY(A43)=1,COUNTIF(FERIADOS,A43)>0),0,1) -> 1 | D43: =D42+C43 -> 30
A44: =A43+1 -> 46308 | B44: =CHOOSE(WEEKDAY(A44),"dom","lun","mar","mié","jue","vie","sáb") -> mar | C44: =IF(OR(WEEKDAY(A44)=1,COUNTIF(FERIADOS,A44)>0),0,1) -> 1 | D44: =D43+C44 -> 31
A45: =A44+1 -> 46309 | B45: =CHOOSE(WEEKDAY(A45),"dom","lun","mar","mié","jue","vie","sáb") -> mié | C45: =IF(OR(WEEKDAY(A45)=1,COUNTIF(FERIADOS,A45)>0),0,1) -> 1 | D45: =D44+C45 -> 32
...

Sheet Cronograma General
A1: Cronograma General – DSC PUCP Workshops (se actualiza automáticamente desde la hoja Predictivo)
A2: Las filas de ejecución muestran la ventana de realización de cada evento (sesiones o día del evento y su consolidación); su preparación figura en la fila 'Preparación transversal de eventos'.
A4: Componente / Fase (EDT) | B4: Fecha Inicio | C4: Fecha Fin | D4: Días lab. | E4: Hito asociado (Acta)
A5: 1. Inicio | B5: =MIN(Predictivo!$F$30) -> 46279 | C5: =MAX(Predictivo!$G$30) -> 46312 | D5: {=INDEX(NLAB,MATCH(C5,FECHAS,0))-INDEX(NLAB,MATCH(B5,FECHAS,0))+1} -> 29 | E5: ="H01 "&MID(Predictivo!$D$8,3,200)&" ("&TEXT(DAY(Predictivo!$F$8),"00")&"/"&TEXT(MONTH(Predictivo!$F$8),"00")&"/"&YEAR(Predictivo!$F$8)&")"&CHAR(10)&"H02 "&MID(Predictivo!$D$9,3,200)&" ("&TEXT(DAY(Predictivo!$F$9),"00")&"/"&TEXT(MONTH(Predictivo!$F$9),"00")&"/"&YEAR(Predictivo!$F$9)&")" -> H01 cta de Constitución aprobada y Gerente de Proyecto designado (14/09/2026) H02 eunión de lanzamiento (kick-off) y responsables por área asignados (21/09/2026)
A6: 2. Planificación | B6: =MIN(Predictivo!$F$43) -> 46280 | C6: =MAX(Predictivo!$G$43) -> 46325 | D6: {=INDEX(NLAB,MATCH(C6,FECHAS,0))-INDEX(NLAB,MATCH(B6,FECHAS,0))+1} -> 39 | E6: ="H03 "&MID(Predictivo!$D$10,3,200)&" ("&TEXT(DAY(Predictivo!$F$10),"00")&"/"&TEXT(MONTH(Predictivo!$F$10),"00")&"/"&YEAR(Predictivo!$F$10)&")" -> H03 lan para la Dirección del Proyecto aprobado (30/10/2026)
A7: 3.1 Patrocinios y adquisiciones | B7: =MIN(Predictivo!$F$74) -> 46326 | C7: =MAX(Predictivo!$G$74) -> 46568 | D7: {=INDEX(NLAB,MATCH(C7,FECHAS,0))-INDEX(NLAB,MATCH(B7,FECHAS,0))+1} -> 199 | E7: ="H04 "&MID(Predictivo!$D$11,3,200)&" ("&TEXT(DAY(Predictivo!$F$11),"00")&"/"&TEXT(MONTH(Predictivo!$F$11),"00")&"/"&YEAR(Predictivo!$F$11)&")"&CHAR(10)&"H06 "&MID(Predictivo!$D$13,3,200)&" ("&TEXT(DAY(Predictivo!$F$13),"00")&"/"&TEXT(MONTH(Predictivo!$F$13),"00")&"/"&YEAR(Predictivo!$F$13)&")" -> H04 nicio formal de la gestión de auspicios (brochure enviado) (06/11/2026) H06 cuerdos de patrocinio firmados – decisión go/no-go financiera (22/01/2027)
A8: 3.2 Publicidad y difusión (incluye web oficial) | B8: =MIN(Predictivo!$F$90) -> 46333 | C8: =MAX(Predictivo!$G$90) -> 46603 | D8: {=INDEX(NLAB,MATCH(C8,FECHAS,0))-INDEX(NLAB,MATCH(B8,FECHAS,0))+1} -> 220 | E8: ="H08 "&MID(Predictivo!$D$15,3,200)&" ("&TEXT(DAY(Predictivo!$F$15),"00")&"/"&TEXT(MONTH(Predictivo!$F$15),"00")&"/"&YEAR(Predictivo!$F$15)&")" -> H08 eb en producción, lanzamiento de campaña e inscripciones abiertas (15/02/2027)
A9: 3.3 – 3.9 Preparación transversal de eventos (reservas, expertos, sílabos y bases) | B9: =MIN(Predictivo!$F$113,Predictivo!$F$114,Predictivo!$F$143,Predictivo!$F$144,Predictivo!$F$173,Predictivo!$F$174,Predictivo!$F$120,Predictivo!$F$150,Predictivo!$F$180,Predictivo!$F$204,Predictivo!$F$205,Predictivo!$F$210,Predictivo!$F$231,Predictivo!$F$232,Predictivo!$F$236,Predictivo!$F$259,Predictivo!$F$260,Predictivo!$F$266,Predictivo!$F$287,Predictivo!$F$288,Predictivo!$F$289,Predictivo!$F$298) -> 46342 | C9: =MAX(Predictivo!$G$113,Predictivo!$G$114,Predictivo!$G$143,Predictivo!$G$144,Predictivo!$G$173,Predictivo!$G$174,Predictivo!$G$120,Predictivo!$G$150,Predictivo!$G$180,Predictivo!$G$204,Predictivo!$G$205,Predictivo!$G$210,Predictivo!$G$231,Predictivo!$G$232,Predictivo!$G$236,Predictivo!$G$259,Predictivo!$G$260,Predictivo!$G$266,Predictivo!$G$287,Predictivo!$G$288,Predictivo!$G$289,Predictivo!$G$298) -> 46423 | D9: {=INDEX(NLAB,MATCH(C9,FECHAS,0))-INDEX(NLAB,MATCH(B9,FECHAS,0))+1} -> 67 | E9: ="H05 "&MID(Predictivo!$D$12,3,200)&" ("&TEXT(DAY(Predictivo!$F$12),"00")&"/"&TEXT(MONTH(Predictivo!$F$12),"00")&"/"&YEAR(Predictivo!$F$12)&")"&CHAR(10)&"H07 "&MID(Predictivo!$D$14,3,200)&" ("&TEXT(DAY(Predictivo!$F$14),"00")&"/"&TEXT(MONTH(Predictivo!$F$14),"00")&"/"&YEAR(Predictivo!$F$14)&")" -> H05 spacios y permisos confirmados (sede alternativa por evento) (15/01/2027) H07 rograma académico, ponentes, mentores y jurados confirmados (05/02/2027)
A10: 3.3 Primera Ronda de Talleres – Módulo I | B10: =MIN(Predictivo!$F$123) -> 46450 | C10: =MAX(Predictivo!$G$123) -> 46476 | D10: {=INDEX(NLAB,MATCH(C10,FECHAS,0))-INDEX(NLAB,MATCH(B10,FECHAS,0))+1} -> 21 | E10: ="H09 "&MID(Predictivo!$D$16,3,200)&" ("&TEXT(DAY(Predictivo!$F$16),"00")&"/"&TEXT(MONTH(Predictivo!$F$16),"00")&"/"&YEAR(Predictivo!$F$16)&")" -> H09 nicio del Módulo I (primer taller) (04/03/2027)
A11: 3.6 Hackathon "Kachimbo" | B11: =MIN(Predictivo!$F$215) -> 46473 | C11: =MAX(Predictivo!$G$215) -> 46476 | D11: {=INDEX(NLAB,MATCH(C11,FECHAS,0))-INDEX(NLAB,MATCH(B11,FECHAS,0))+1} -> 3 | E11: ="H10 "&MID(Predictivo!$D$17,3,200)&" ("&TEXT(DAY(Predictivo!$F$17),"00")&"/"&TEXT(MONTH(Predictivo!$F$17),"00")&"/"&YEAR(Predictivo!$F$17)&")" -> H10 ackathon Kachimbo – cierre del Módulo I (27/03/2027)
A12: 3.4 Segunda Ronda de Talleres – Módulo II | B12: =MIN(Predictivo!$F$153) -> 46478 | C12: =MAX(Predictivo!$G$153) -> 46504 | D12: {=INDEX(NLAB,MATCH(C12,FECHAS,0))-INDEX(NLAB,MATCH(B12,FECHAS,0))+1} -> 23 | E12: —
A13: 3.7 Competencia de Kaggle | B13: =MIN(Predictivo!$F$242) -> 46494 | C13: =MAX(Predictivo!$G$242) -> 46504 | D13: {=INDEX(NLAB,MATCH(C13,FECHAS,0))-INDEX(NLAB,MATCH(B13,FECHAS,0))+1} -> 9 | E13: ="H11 "&MID(Predictivo!$D$19,3,200)&" ("&TEXT(DAY(Predictivo!$F$19),"00")&"/"&TEXT(MONTH(Predictivo!$F$19),"00")&"/"&YEAR(Predictivo!$F$19)&")" -> H11 ompetencia de Kaggle – cierre del Módulo II (24/04/2027)
A14: 3.8 Torneo de Vibecoding (8 h) | B14: =MIN(Predictivo!$F$271) -> 46536 | C14: =MAX(Predictivo!$G$271) -> 46539 | D14: {=INDEX(NLAB,MATCH(C14,FECHAS,0))-INDEX(NLAB,MATCH(B14,FECHAS,0))+1} -> 3 | E14: ="H12 "&MID(Predictivo!$D$20,3,200)&" ("&TEXT(DAY(Predictivo!$F$20),"00")&"/"&TEXT(MONTH(Predictivo!$F$20),"00")&"/"&YEAR(Predictivo!$F$20)&")" -> H12 ackathon de 8 h "Torneo de Vibecoding" realizado (29/05/2027)
A15: 3.5 Tercera Ronda de Talleres – Módulo III (GCP) | B15: =MIN(Predictivo!$F$183) -> 46541 | C15: =MAX(Predictivo!$G$183) -> 46568 | D15: {=INDEX(NLAB,MATCH(C15,FECHAS,0))-INDEX(NLAB,MATCH(B15,FECHAS,0))+1} -> 22 | E15: ="H13 "&MID(Predictivo!$D$21,3,200)&" ("&TEXT(DAY(Predictivo!$F$21),"00")&"/"&TEXT(MONTH(Predictivo!$F$21),"00")&"/"&YEAR(Predictivo!$F$21)&")" -> H13 remiación GCP – cierre del Módulo III (26/06/2027)
A16: 3.9 Hackathon Internacional de 24 h | B16: =MIN(Predictivo!$F$301,Predictivo!$F$303) -> 46599 | C16: =MAX(Predictivo!$G$301,Predictivo!$G$303) -> 46602 | D16: {=INDEX(NLAB,MATCH(C16,FECHAS,0))-INDEX(NLAB,MATCH(B16,FECHAS,0))+1} -> 3 | E16: ="H14 "&MID(Predictivo!$D$22,3,200)&" ("&TEXT(DAY(Predictivo!$F$22),"00")&"/"&TEXT(MONTH(Predictivo!$F$22),"00")&"/"&YEAR(Predictivo!$F$22)&")" -> H14 ackathon Internacional de 24 h realizado (evento cumbre) (01/08/2027)
A17: 4. Seguimiento y control (informes por evento y reportes) | B17: =MIN(Predictivo!$F$310) -> 46293 | C17: =MAX(Predictivo!$G$310) -> 46618 | D17: {=INDEX(NLAB,MATCH(C17,FECHAS,0))-INDEX(NLAB,MATCH(B17,FECHAS,0))+1} -> 266 | E17: ="H15 "&MID(Predictivo!$D$23,3,200)&" ("&TEXT(DAY(Predictivo!$F$23),"00")&"/"&TEXT(MONTH(Predictivo!$F$23),"00")&"/"&YEAR(Predictivo!$F$23)&")"&CHAR(10)&"H16 "&MID(Predictivo!$D$24,3,200)&" ("&TEXT(DAY(Predictivo!$F$24),"00")&"/"&TEXT(MONTH(Predictivo!$F$24),"00")&"/"&YEAR(Predictivo!$F$24)&")"&CHAR(10)&"H17 "&MID(Predictivo!$D$25,3,200)&" ("&TEXT(DAY(Predictivo!$F$25),"00")&"/"&TEXT(MONTH(Predictivo!$F$25),"00")&"/"&YEAR(Predictivo!$F$25)&")"&CHAR(10)&"H18 "&MID(Predictivo!$D$26,3,200)&" ("&TEXT(DAY(Predictivo!$F$26),"00")&"/"&TEXT(MONTH(Predictivo!$F$26),"00")&"/"&YEAR(Predictivo!$F$26)&")"&CHAR(10)&"H19 "&MID(Predictivo!$D$27,3,200)&" ("&TEXT(DAY(Predictivo!$F$27),"00")&"/"&TEXT(MONTH(Predictivo!$F$27),"00")&"/"&YEAR(Predictivo!$F$27)&")" -> H15 eporte de seguimiento N.° 1 presentado (Módulo I y Kachimbo) (02/04/2027) H16 eporte de seguimiento N.° 2 presentado (Módulo II y Kaggle) (30/04/2027) H17 eporte de seguimiento N.° 3 presentado (Torneo de Vibecoding) (04/06/2027) H18 eporte de seguimiento N.° 4 presentado (Módulo III y premiación GCP) (02/07/2027) H19 eporte de seguimiento N.° 5 presentado (Hackathon de 24 h) (05/08/2027)
A18: 5. Cierre | B18: =MIN(Predictivo!$F$336) -> 46601 | C18: =MAX(Predictivo!$G$336) -> 46619 | D18: {=INDEX(NLAB,MATCH(C18,FECHAS,0))-INDEX(NLAB,MATCH(B18,FECHAS,0))+1} -> 16 | E18: ="H20 "&MID(Predictivo!$D$28,3,200)&" ("&TEXT(DAY(Predictivo!$F$28),"00")&"/"&TEXT(MONTH(Predictivo!$F$28),"00")&"/"&YEAR(Predictivo!$F$28)&")"&CHAR(10)&"H21 "&MID(Predictivo!$D$29,3,200)&" ("&TEXT(DAY(Predictivo!$F$29),"00")&"/"&TEXT(MONTH(Predictivo!$F$29),"00")&"/"&YEAR(Predictivo!$F$29)&")" -> H20 nforme final de resultados aprobado y enviado a sponsors y PUCP (13/08/2027) H21 cta de cierre firmada – fin del proyecto (20/08/2027)

Sheet Notas y criterios
A1: CRITERIOS DE PROGRAMACIÓN Y LECTURA DEL CRONOGRAMA
A2: 1. Base del cronograma: Acta de Constitución (14/09/2026) y EDT validada por el docente (19/09/2026). Cada entregable de la EDT (columna ENTREGABLE) se descompone en actividades (columna NOMBRE DE LA TAREA) con los campos mínimos vistos en clase: ID, duración, fechas de inicio y fin, predecesoras, recursos, estado y % de avance.
A3: 2. Codificación: el ID de cada actividad hereda el código de su paquete de la EDT (p. ej., 3.3.2.3 es la tercera actividad del paquete 3.3.2). Los hitos del Acta se identifican como H01–H21 y se listan al inicio con su fecha tope.
A4: 3. Calendario: días laborables de lunes a sábado (los talleres y eventos se realizan jueves y sábados), excluyendo domingos y feriados nacionales 2026-2027 (hoja Calendario). La duración está en días laborables. Excepción: la Hackathon de 24 h (sábado 31/07 a domingo 01/08) se registra con 2 días calendario.
A5: 4. Tipos de fecha: negrita azul = fecha fija comprometida (sesiones, eventos, reuniones de aprobación y presentaciones de reportes del Acta); azul normal = fecha 'no antes de' (ventanas planificadas, p. ej. reservas de enero); negro = fecha calculada por fórmula a partir de predecesoras o, para la preparación inmediata de un evento, contando días laborables hacia atrás desde su fecha fija (programación 'lo más tarde posible').
A6: 5. Dependencias: se usa la relación fin-inicio (FI), la más común (Sesión 5). La notación 'FI+nd' indica un retraso de n días. Se combinan dependencias obligatorias (p. ej., sílabos antes de la sesión), discrecionales (p. ej., retrospectiva al cierre del módulo) y externas (DAES: 7 días hábiles; Pabellón V: 2 días hábiles; NTT Data; proveedor de merchandising).
A7: 6. Estimación: juicio experto y estimación análoga con base en eventos previos de DSC PUCP; los trámites se estiman con los plazos oficiales de la PUCP. Se aplican reservas de contingencia (análisis de reservas): p. ej., 3 días entre la revisión del Plan y su aprobación, 4 días entre la prueba técnica y cada evento, y solicitudes a la DAES con 14 días laborables de anticipación (el doble del plazo mínimo, respuesta R5).
A8: 7. Ruta crítica: se calculó con el método de la ruta crítica (pasada hacia adelante y hacia atrás, Sesión 6) considerando las fechas fijas y las fechas tope de los hitos del Acta. Son críticas (holgura total = 0): las sesiones y eventos con fecha fija; la cadena de patrocinios brochure → negociación → firma → go/no-go (22/01/2027); la reserva de NTT Data y el plan de seguridad (E2, 15/01/2027); la confirmación de expertos y bases del evento de 24 h (E4, 05/02/2027); y la cadena final evento de 24 h → consolidación → Reporte N.° 5 → informe final → acta de cierre (20/08/2027).
A9: 8. Holguras: la columna HOLGURA LIBRE es dinámica (fórmula): si una fecha cambia y se genera un conflicto, aparece en negativo y en rojo. La columna HOLGURA TOTAL es el resultado del análisis CPM de la línea base y debe recalcularse si se modifica la red de actividades.
A10: 9. Nivelación de recursos: las confirmaciones de ponentes (Relaciones Exteriores) se adelantaron a noviembre y diciembre de 2026 para no coincidir con el cierre de patrocinios de enero; las inducciones de voluntarios y las pruebas técnicas se ubicaron en días sin sesiones para no sobrecargar a Logística; el Taller de pitch pasa al miércoles 24/03 por Jueves Santo (respuesta R4).
A11: 10. Seguimiento: actualizar la FECHA DE ESTADO (hoja Calendario) y el % DE AVANCE en cada reunión semanal. El ESTADO se calcula solo: Completado, En progreso, No iniciado o Atrasado (fin planificado anterior a la fecha de estado sin 100 %). Los hitos muestran Cumplido, Pendiente, En riesgo (fecha prevista posterior a la fecha tope) o Atrasado.
A12: 11. Esfuerzo continuo: actividades de nivel de esfuerzo (reunión semanal, control de cambios, seguimiento de desembolsos, difusión continua, control de merchandising y confirmación de ponentes) se muestran en gris y no forman parte del cálculo de la ruta crítica.
