Workbook

Sheet Presupuesto por Entregable
A1: Presupuesto por Entregable de la EDT — DSC PUCP Workshops
A3: Tabla 1: Tarifas por recurso humano
A4: Sigla | B4: Recurso (según el cronograma) | C4: Tarifa por hora (S/) | D4: Modalidad | J4: Nota
A5: PAT | B5: Patrocinador (L. Flores) | C5: 0 | D5: Voluntario (sin remuneración)
A6: GP | B6: Gerente de Proyecto (L. Alvites) | C6: 0 | D6: Voluntario (sin remuneración)
A7: EQ5 | B7: Equipo 5 (Planificación) | C7: 0 | D7: Voluntario (sin remuneración)
A8: DIR | B8: Directores de área (reuniones conjuntas) | C8: 0 | D8: Voluntario (sin remuneración)
A9: LOG | B9: Logística y Eventos (F. Caceres) | C9: 0 | D9: Voluntario (sin remuneración)
A10: MKT | B10: Marketing y Comunidad (A. Quispe) | C10: 0 | D10: Voluntario (sin remuneración)
A11: REX | B11: Relaciones Exteriores (S. Cruz) | C11: 0 | D11: Voluntario (sin remuneración)
A12: FIN | B12: Finanzas y Legalidad (E. Chachayma) | C12: 0 | D12: Voluntario (sin remuneración)
A13: RH | B13: RR.HH. (M. Colala) | C13: 0 | D13: Voluntario (sin remuneración)
A14: SW | B14: Desarrollo de Software (R. Chang) | C14: 0 | D14: Voluntario (sin remuneración)
A15: INF | B15: Infraestructura y Ciberseguridad (R. Sanchez) | C15: 0 | D15: Voluntario (sin remuneración)
A16: STF | B16: Voluntarios DSC | C16: 0 | D16: Voluntario (sin remuneración)
... A20: PAB | B20: Pabellón V (P. Corrado, F. Solari) | C20: 0 | D20: Cedido por la PUCP
A22: Tabla 2: Presupuesto por entregable
A23: Código EDT | B23: Entregable / recurso | C23: Cuenta de control | D23: Cantidad | E23: Tarifa (S/) | F23: Tiempo | G23: Unidad | H23: Subtotal (S/) | I23: Tipo de recurso | J23: Base de estimación / supuesto
A24: 1 | B24: INICIO
A25: 1.1 | B25: Acta de constitución del proyecto (1 día: 14/09/26 – 14/09/26) | H25: =SUM(H26:H27) -> 0 | J25: Actividades: 1.1.1
B26: Patrocinador (L. Flores) | C26: 1 | D26: 1 | E26: =$C$5 -> 0 | F26: 2 | G26: horas c/u | H26: =D26*E26*F26 -> 0 | I26: Personal
B27: Gerente de Proyecto (L. Alvites) | C27: 1 | D27: 1 | E27: =$C$6 -> 0 | F27: 2 | G27: horas c/u | H27: =D27*E27*F27 -> 0 | I27: Personal
A28: 1.2 | B28: Declaración preliminar del alcance (4 días: 15/09/26 – 18/09/26) | H28: =SUM(H29:H31) -> 0 | J28: Actividades: 1.2.1, 1.2.2
B29: Patrocinador (L. Flores) | C29: 1 | D29: 1 | E29: =$C$5 -> 0 | F29: 2 | G29: horas c/u | H29: =D29*E29*F29 -> 0 | I29: Personal
B30: Gerente de Proyecto (L. Alvites) | C30: 1 | D30: 1 | E30: =$C$6 -> 0 | F30: 2 | G30: horas c/u | H30: =D30*E30*F30 -> 0 | I30: Personal
B31: Equipo 5 (Planificación) | C31: 1 | D31: 5 | E31: =$C$7 -> 0 | F31: 6 | G31: horas c/u | H31: =D31*E31*F31 -> 0 | I31: Personal
A32: 1.3 | B32: Acuerdos iniciales con patrocinadores (22 días: 22/09/26 – 17/10/26) | H32: =SUM(H33:H34) -> 0 | J32: Actividades: 1.3.1, 1.3.2, 1.3.3
B33: Gerente de Proyecto (L. Alvites) | C33: 1 | D33: 1 | E33: =$C$6 -> 0 | F33: 24 | G33: horas c/u | H33: =D33*E33*F33 -> 0 | I33: Personal
B34: Relaciones Exteriores (S. Cruz) | C34: 1 | D34: 1 | E34: =$C$11 -> 0 | F34: 56 | G34: horas c/u | H34: =D34*E34*F34 -> 0 | I34: Personal
A35: 1.4 | B35: Registro de interesados (6 días: 15/09/26 – 21/09/26) | H35: =SUM(H36:H38) -> 0 | J35: Actividades: 1.4.1, 1.4.2
B36: Gerente de Proyecto (L. Alvites) | C36: 1 | D36: 1 | E36: =$C$6 -> 0 | F36: 2 | G36: horas c/u | H36: =D36*E36*F36 -> 0 | I36: Personal
B37: Equipo 5 (Planificación) | C37: 1 | D37: 5 | E37: =$C$7 -> 0 | F37: 10 | G37: horas c/u | H37: =D37*E37*F37 -> 0 | I37: Personal
B38: Directores de área (reuniones conjuntas) | C38: 1 | D38: 7 | E38: =$C$8 -> 0 | F38: 2 | G38: horas c/u | H38: =D38*E38*F38 -> 0 | I38: Personal
G39: Total 1. Inicio | H39: =H25+H28+H32+H35 -> 0
A40: 2 | B40: PLANIFICACIÓN
A41: 2.1 | B41: Plan de Gestión del Proyecto (12 días: 17/10/26 – 30/10/26) | H41: =SUM(H42:H45) -> 0 | J41: Actividades: 2.1.1, 2.1.2, 2.1.3
B42: Patrocinador (L. Flores) | C42: 2 | D42: 1 | E42: =$C$5 -> 0 | F42: 2 | G42: horas c/u | H42: =D42*E42*F42 -> 0 | I42: Personal
B43: Gerente de Proyecto (L. Alvites) | C43: 2 | D43: 1 | E43: =$C$6 -> 0 | F43: 18 | G43: horas c/u | H43: =D43*E43*F43 -> 0 | I43: Personal
B44: Equipo 5 (Planificación) | C44: 2 | D44: 5 | E44: =$C$7 -> 0 | F44: 10 | G44: horas c/u | H44: =D44*E44*F44 -> 0 | I44: Personal
B45: Directores de área (reuniones conjuntas) | C45: 2 | D45: 7 | E45: =$C$8 -> 0 | F45: 6 | G45: horas c/u | H45: =D45*E45*F45 -> 0 | I45: Personal
...

Sheet Flujo de Caja
A1: Flujo de Caja — enero a agosto 2027
A2: Solo desembolsos monetarios, ubicados en el mes en que el cronograma detallado programa la compra o el evento. Los auspicios entran en tramos al menos 30 días antes de los eventos que financian (R2).
A4: Concepto | B4: Mes 1 Ene-27 | C4: Mes 2 Feb-27 | D4: Mes 3 Mar-27 | E4: Mes 4 Abr-27 | F4: Mes 5 May-27 | G4: Mes 6 Jun-27 | H4: Mes 7 Jul-27 | I4: Mes 8 Ago-27 | J4: Total | L4: Tramo de auspicios | M4: % de la meta | N4: Fecha límite de desembolso
A5: Ingresos (*) | L5: Tramo 1 (febrero) | M5: 0.3 | N5: Antes del 02/02 — orden de compra del merchandising (3.1.3.1) y 30 días antes del Módulo I
A6: Capital semilla DSC PUCP | B6: ='Presupuesto por Entregable'!H457 -> 300 | J6: =SUM(B6:I6) -> 300 | L6: Tramo 2 (abril) | M6: 0.2 | N6: Antes del 29/04 — 30 días antes del Torneo de Vibecoding
A7: Auspicios — tramo 1 (30 %) | C7: ='Presupuesto por Entregable'!$H$458*$M$5 -> 5460 | J7: =SUM(B7:I7) -> 5460 | L7: Tramo 3 (junio) | M7: 0.5 | N7: Antes del 30/06 — 30 días antes de la hackathon de 24 h
A8: Auspicios — tramo 2 (20 %) | E8: ='Presupuesto por Entregable'!$H$458*$M$6 -> 3640 | J8: =SUM(B8:I8) -> 3640 | L8: Total | M8: =SUM(M5:M7) -> 1
A9: Auspicios — tramo 3 (50 %) | G9: ='Presupuesto por Entregable'!$H$458*$M$7 -> 9100 | J9: =SUM(B9:I9) -> 9100
A10: Total Ingresos | B10: =SUM(B6:B9) -> 300 | C10: =SUM(C6:C9) -> 5460 | D10: =SUM(D6:D9) -> 0 | E10: =SUM(E6:E9) -> 3640 | F10: =SUM(F6:F9) -> 0 | G10: =SUM(G6:G9) -> 9100 | H10: =SUM(H6:H9) -> 0 | I10: =SUM(I6:I9) -> 0 | J10: =SUM(B10:I10) -> 18500
A11: Egresos
A12: 3.1 Patrocinios y adquisiciones (merchandising) | C12: ='Presupuesto por Entregable'!H414 -> 1490 | J12: =SUM(B12:I12) -> 1490
A13: 3.2 Publicidad y difusión | B13: ='Presupuesto por Entregable'!H97 -> 60 | C13: ='Presupuesto por Entregable'!H98+'Presupuesto por Entregable'!H99+'Presupuesto por Entregable'!H100/'Presupuesto por Entregable'!F100 -> 590 | D13: ='Presupuesto por Entregable'!H100/'Presupuesto por Entregable'!F100 -> 80 | E13: ='Presupuesto por Entregable'!H100/'Presupuesto por Entregable'!F100 -> 80 | F13: ='Presupuesto por Entregable'!H100/'Presupuesto por Entregable'!F100 -> 80 | G13: ='Presupuesto por Entregable'!H100/'Presupuesto por Entregable'!F100 -> 80 | H13: ='Presupuesto por Entregable'!H100/'Presupuesto por Entregable'!F100 -> 80 | J13: =SUM(B13:I13) -> 1050
A14: 3.3 Primera Ronda de Talleres — Módulo I | D14: ='Presupuesto por Entregable'!H416 -> 560 | J14: =SUM(B14:I14) -> 560
A15: 3.6 Hackathon "Kachimbo" | D15: ='Presupuesto por Entregable'!H419 -> 500 | J15: =SUM(B15:I15) -> 500
A16: 3.4 Segunda Ronda de Talleres — Módulo II | E16: ='Presupuesto por Entregable'!H417 -> 560 | J16: =SUM(B16:I16) -> 560
A17: 3.7 Competencia de Kaggle | E17: ='Presupuesto por Entregable'!H420 -> 500 | J17: =SUM(B17:I17) -> 500
A18: 3.8 Torneo de Vibecoding (8 h) | F18: ='Presupuesto por Entregable'!H421 -> 2290 | J18: =SUM(B18:I18) -> 2290
A19: 3.5 Tercera Ronda de Talleres — Módulo III y premiación GCP | G19: ='Presupuesto por Entregable'!H418 -> 980 | J19: =SUM(B19:I19) -> 980
A20: 3.9 Hackathon Internacional de 24 h | H20: ='Presupuesto por Entregable'!H422 -> 6590 | J20: =SUM(B20:I20) -> 6590
A21: Total Egresos | B21: =SUM(B12:B20) -> 60 | C21: =SUM(C12:C20) -> 2080 | D21: =SUM(D12:D20) -> 1140 | E21: =SUM(E12:E20) -> 1140 | F21: =SUM(F12:F20) -> 2370 | G21: =SUM(G12:G20) -> 1060 | H21: =SUM(H12:H20) -> 6670 | I21: =SUM(I12:I20) -> 0 | J21: =SUM(B21:I21) -> 14520
A22: Saldo del mes (ingresos − egresos) | B22: =B10-B21 -> 240 | C22: =C10-C21 -> 3380 | D22: =D10-D21 -> -1140 | E22: =E10-E21 -> 2500 | F22: =F10-F21 -> -2370 | G22: =G10-G21 -> 8040 | H22: =H10-H21 -> -6670 | I22: =I10-I21 -> 0 | J22: =SUM(B22:I22) -> 3980
A23: Total Acumulado | B23: =B10-B21 -> 240 | C23: =B23+C10-C21 -> 3620 | D23: =C23+D10-D21 -> 2480 | E23: =D23+E10-E21 -> 4980 | F23: =E23+F10-F21 -> 2610 | G23: =F23+G10-G21 -> 10650 | H23: =G23+H10-H21 -> 3980 | I23: =H23+I10-I21 -> 3980
A25: Comprobación: saldo final esperado = superávit + contingencia + gestión | B25: ='Presupuesto por Entregable'!H460+'Presupuesto por Entregable'!H448+'Presupuesto por Entregable'!H450 -> 3980
A26: Diferencia con el acumulado de agosto (debe ser 0) | B26: =I23-B25 -> 0
A27: Saldo mínimo del periodo (no debe ser negativo) | B27: =MIN(B23:I23) -> 240
A29: * Los ingresos provienen del capital semilla de DSC PUCP y de los auspicios corporativos (P11: los participantes no pagan inscripción).
A30: * Los egresos corresponden a las cuentas de control de la hoja 'Presupuesto por Entregable'; las reservas no se programan porque solo se usan si ocurre el riesgo o el imprevisto.
A31: * En enero solo se gasta el dominio web, dentro del tope de S/ 300 del capital semilla. Ninguna compra se compromete antes del primer desembolso (R2).
A32: * En un entorno ideal, el total acumulado de agosto es igual al superávit más las reservas no utilizadas.

Sheet Curva S
A1: Curva S — costo planificado acumulado vs. línea base y financiamiento
A2: Se grafica contra la línea base de costos, no contra la reserva de gestión (sesión 7).
A4: Mes | B4: Costo planificado del mes | C4: Costo acumulado | D4: Línea base de costos | E4: Financiamiento acumulado
A5: Ene-27 | B5: ='Flujo de Caja'!B21 -> 60 | C5: =B5 -> 60 | D5: ='Presupuesto por Entregable'!$H$449 -> 15680 | E5: ='Flujo de Caja'!B10 -> 300
A6: Feb-27 | B6: ='Flujo de Caja'!C21 -> 2080 | C6: =C5+B6 -> 2140 | D6: ='Presupuesto por Entregable'!$H$449 -> 15680 | E6: =E5+'Flujo de Caja'!C10 -> 5760
A7: Mar-27 | B7: ='Flujo de Caja'!D21 -> 1140 | C7: =C6+B7 -> 3280 | D7: ='Presupuesto por Entregable'!$H$449 -> 15680 | E7: =E6+'Flujo de Caja'!D10 -> 5760
A8: Abr-27 | B8: ='Flujo de Caja'!E21 -> 1140 | C8: =C7+B8 -> 4420 | D8: ='Presupuesto por Entregable'!$H$449 -> 15680 | E8: =E7+'Flujo de Caja'!E10 -> 9400
A9: May-27 | B9: ='Flujo de Caja'!F21 -> 2370 | C9: =C8+B9 -> 6790 | D9: ='Presupuesto por Entregable'!$H$449 -> 15680 | E9: =E8+'Flujo de Caja'!F10 -> 9400
A10: Jun-27 | B10: ='Flujo de Caja'!G21 -> 1060 | C10: =C9+B10 -> 7850 | D10: ='Presupuesto por Entregable'!$H$449 -> 15680 | E10: =E9+'Flujo de Caja'!G10 -> 18500
A11: Jul-27 | B11: ='Flujo de Caja'!H21 -> 6670 | C11: =C10+B11 -> 14520 | D11: ='Presupuesto por Entregable'!$H$449 -> 15680 | E11: =E10+'Flujo de Caja'!H10 -> 18500
A12: Ago-27 | B12: ='Flujo de Caja'!I21 -> 0 | C12: =C11+B12 -> 14520 | D12: ='Presupuesto por Entregable'!$H$449 -> 15680 | E12: =E11+'Flujo de Caja'!I10 -> 18500
